<?xml version="1.0"?>
<robot xmlns:xacro="http://www.ros.org/wiki/xacro">
  <!-- NOTE: joint must match the name of the module -->
  <xacro:macro name="x5" params="joint child">
    <link name="${joint}/INPUT_INTERFACE">
      <visual>
        <origin xyz="0 0 0.0155" rpy="3.14157 0 0" />
        <geometry>
          <mesh filename="package://hebiros/meshes/x5.stl"/>
        </geometry>
        <xacro:red_material/>
      </visual>
      <collision>
        <origin xyz="0 0 0.0155" rpy="3.14157 0 0" />
        <geometry>
          <mesh filename="package://hebiros/meshes/x5.stl"/>
        </geometry>
      </collision>
      <inertial>
        <origin xyz="0 0 0.0155" rpy="3.14157 0 0" />
        <mass value="0.335"/>
        <inertia  ixx="1.0" ixy="0.0"  ixz="0.0"  iyy="1.0"  iyz="0.0"  izz="1.0"/>
      </inertial>
    </link>
    <joint name="${joint}" type="revolute">
      <parent link="${joint}/INPUT_INTERFACE"/>
      <child link="${child}/INPUT_INTERFACE"/>
      <origin xyz="0 0 0.031" rpy="0 0 0"/>
      <axis xyz="0 0 1"/>
      <limit effort="9.0" lower="-10.0" upper="10.0" velocity="2.208932"/>
      <dynamics damping="0.2" friction="0.2"/>
    </joint>
    <transmission name="${joint}/transmission">
    <type>transmission_interface/SimpleTransmission</type>
      <joint name="${joint}">
        <hardwareInterface>hardware_interface/EffortJointInterface</hardwareInterface>
      </joint>
      <actuator name="${joint}/actuator">
        <hardwareInterface>hardware_interface/EffortJointInterface</hardwareInterface>
        <mechanicalReduction>1</mechanicalReduction>
      </actuator>
    </transmission>
    <gazebo reference="${joint}/INPUT_INTERFACE">
      <selfCollide>true</selfCollide>
    </gazebo>
  </xacro:macro>
</robot>

