<?xml version="1.0" ?>
<!-- =================================================================================== -->
<!-- |    This document was autogenerated by xacro from x_demo.xacro                   | -->
<!-- |    EDITING THIS FILE BY HAND IS NOT RECOMMENDED                                 | -->
<!-- =================================================================================== -->
<robot name="arm_demo" xmlns:xacro="http://www.ros.org/wiki/xacro">
  <!-- *************************** XACRO MACROS *************************** -->
  <!-- ************************* ROBOT DEFINITION ************************* -->
  <link name="world"/>
  <joint name="world_joint" type="fixed">
    <origin rpy="0 0 0" xyz="0 0 0"/>
    <parent link="world"/>
    <child link="base"/>
  </joint>
  <!-- just for visualization: base post -->
  <link name="base">
    <visual>
      <origin rpy="0 0 0" xyz=".125 0 -.0254"/>
      <geometry>
        <box size="0.25 0.5 0.0508"/>
      </geometry>
      <material name="silver">
        <color rgba="0.6 0.6 0.6 1"/>
      </material>
    </visual>
    <collision>
      <origin rpy="0 0 0" xyz=".125 0 -.0254"/>
      <geometry>
        <box size="0.25 0.5 0.0508"/>
      </geometry>
    </collision>
    <inertial>
      <origin rpy="0 0 0" xyz=".125 0 -.0254"/>
      <mass value="1.0"/>
      <inertia ixx="1.0" ixy="0.0" ixz="0.0" iyy="1.0" iyz="0.0" izz="1.0"/>
    </inertial>
  </link>
  <joint name="base_base" type="fixed">
    <parent link="base"/>
    <child link="HEBI/base/INPUT_INTERFACE"/>
    <origin rpy="0 0 0" xyz="0 0 0"/>
  </joint>
  <link name="HEBI/base/INPUT_INTERFACE">
    <visual>
      <origin rpy="3.14157 0 0" xyz="0 0 0.0155"/>
      <geometry>
        <mesh filename="package://hebiros/meshes/x5.stl"/>
      </geometry>
      <material name="red">
        <color rgba=".82 0.06 0.06 1"/>
      </material>
    </visual>
    <collision>
      <origin rpy="3.14157 0 0" xyz="0 0 0.0155"/>
      <geometry>
        <mesh filename="package://hebiros/meshes/x5.stl"/>
      </geometry>
    </collision>
    <inertial>
      <origin rpy="3.14157 0 0" xyz="0 0 0.0155"/>
      <mass value="0.335"/>
      <inertia ixx="1.0" ixy="0.0" ixz="0.0" iyy="1.0" iyz="0.0" izz="1.0"/>
    </inertial>
  </link>
  <joint name="HEBI/base" type="revolute">
    <parent link="HEBI/base/INPUT_INTERFACE"/>
    <child link="shoulder_bracket/INPUT_INTERFACE"/>
    <origin rpy="0 0 0" xyz="0 0 0.031"/>
    <axis xyz="0 0 1"/>
    <limit effort="9.0" lower="-10.0" upper="10.0" velocity="2.208932"/>
    <dynamics damping="0.2" friction="0.2"/>
  </joint>
  <transmission name="HEBI/base/transmission">
    <type>transmission_interface/SimpleTransmission</type>
    <joint name="HEBI/base">
      <hardwareInterface>hardware_interface/EffortJointInterface</hardwareInterface>
    </joint>
    <actuator name="HEBI/base/actuator">
      <hardwareInterface>hardware_interface/EffortJointInterface</hardwareInterface>
      <mechanicalReduction>1</mechanicalReduction>
    </actuator>
  </transmission>
  <gazebo reference="HEBI/base/INPUT_INTERFACE">
    <selfCollide>true</selfCollide>
  </gazebo>
  <link name="shoulder_bracket/INPUT_INTERFACE">
    <visual>
      <origin rpy="1.57075 0 1.57075" xyz="0 0 0"/>
      <geometry>
        <mesh filename="package://hebiros/meshes/x_wrist.stl"/>
      </geometry>
      <material name="silver">
        <color rgba="0.6 0.6 0.6 1"/>
      </material>
    </visual>
    <collision>
      <origin rpy="1.57075 0 1.57075" xyz="0 0 0"/>
      <geometry>
        <mesh filename="package://hebiros/meshes/x_wrist.stl"/>
      </geometry>
    </collision>
    <inertial>
      <origin rpy="1.57075 0 1.57075" xyz="0 0 0"/>
      <mass value="0.1"/>
      <inertia ixx="1.0" ixy="0.0" ixz="0.0" iyy="1.0" iyz="0.0" izz="1.0"/>
    </inertial>
  </link>
  <joint name="shoulder_bracket/OUTPUT_INTERFACE" type="fixed">
    <parent link="shoulder_bracket/INPUT_INTERFACE"/>
    <child link="HEBI/shoulder/INPUT_INTERFACE"/>
    <!--    <origin xyz="0 .03685 .05715" rpy="-1.57075 0 3.14157"/>-->
    <origin rpy="-1.57075 0 0" xyz="0 .04235 .05715"/>
  </joint>
  <gazebo reference="shoulder_bracket/INPUT_INTERFACE">
    <selfCollide>true</selfCollide>
  </gazebo>
  <link name="HEBI/shoulder/INPUT_INTERFACE">
    <visual>
      <origin rpy="3.14157 0 0" xyz="0 0 0.0155"/>
      <geometry>
        <mesh filename="package://hebiros/meshes/x5.stl"/>
      </geometry>
      <material name="red">
        <color rgba=".82 0.06 0.06 1"/>
      </material>
    </visual>
    <collision>
      <origin rpy="3.14157 0 0" xyz="0 0 0.0155"/>
      <geometry>
        <mesh filename="package://hebiros/meshes/x5.stl"/>
      </geometry>
    </collision>
    <inertial>
      <origin rpy="3.14157 0 0" xyz="0 0 0.0155"/>
      <mass value="0.335"/>
      <inertia ixx="1.0" ixy="0.0" ixz="0.0" iyy="1.0" iyz="0.0" izz="1.0"/>
    </inertial>
  </link>
  <joint name="HEBI/shoulder" type="revolute">
    <parent link="HEBI/shoulder/INPUT_INTERFACE"/>
    <child link="shoulder_elbow/INPUT_INTERFACE"/>
    <origin rpy="0 0 0" xyz="0 0 0.031"/>
    <axis xyz="0 0 1"/>
    <limit effort="9.0" lower="-10.0" upper="10.0" velocity="2.208932"/>
    <dynamics damping="0.2" friction="0.2"/>
  </joint>
  <transmission name="HEBI/shoulder/transmission">
    <type>transmission_interface/SimpleTransmission</type>
    <joint name="HEBI/shoulder">
      <hardwareInterface>hardware_interface/EffortJointInterface</hardwareInterface>
    </joint>
    <actuator name="HEBI/shoulder/actuator">
      <hardwareInterface>hardware_interface/EffortJointInterface</hardwareInterface>
      <mechanicalReduction>1</mechanicalReduction>
    </actuator>
  </transmission>
  <gazebo reference="HEBI/shoulder/INPUT_INTERFACE">
    <selfCollide>true</selfCollide>
  </gazebo>
  <link name="shoulder_elbow/INPUT_INTERFACE">
    <visual>
      <origin rpy="0 0 3.14157" xyz="-.04 .03 .0075"/>
      <geometry>
        <mesh filename="package://hebiros/meshes/x_output_bracket.stl"/>
      </geometry>
      <material name="black">
        <color rgba="0 0 0 1"/>
      </material>
    </visual>
    <visual>
      <origin rpy="0 1.57075 0" xyz="-0.1904 0 .016075"/>
      <geometry>
        <cylinder length="0.33" radius=".015875"/>
      </geometry>
      <material name="silver">
        <color rgba="0.6 0.6 0.6 1"/>
      </material>
    </visual>
    <visual>
      <origin rpy="1.57075 0 -1.57075" xyz="-0.3554 -.075 -.0125"/>
      <geometry>
        <mesh filename="package://hebiros/meshes/x_mounting_bracket.stl"/>
      </geometry>
      <material name="black">
        <color rgba="0 0 0 1"/>
      </material>
    </visual>
    <collision>
      <origin rpy="0 0 3.14157" xyz="-.04 .03 .0075"/>
      <geometry>
        <mesh filename="package://hebiros/meshes/x_output_bracket.stl"/>
      </geometry>
    </collision>
    <collision>
      <origin rpy="0 1.57075 0" xyz="-0.1904 0 .016075"/>
      <geometry>
        <cylinder length="0.33" radius=".015875"/>
      </geometry>
    </collision>
    <collision>
      <origin rpy="1.57075 0 -1.57075" xyz="-0.3554 -.075 -.0125"/>
      <geometry>
        <mesh filename="package://hebiros/meshes/x_mounting_bracket.stl"/>
      </geometry>
    </collision>
    <inertial>
      <origin rpy="0 0 3.14157" xyz="-.04 .03 .0075"/>
      <mass value="0.01"/>
      <inertia ixx="1.0" ixy="0.0" ixz="0.0" iyy="1.0" iyz="0.0" izz="1.0"/>
    </inertial>
    <inertial>
      <origin rpy="0 1.57075 0" xyz="-0.1904 0 .016075"/>
      <mass value="0.38"/>
      <inertia ixx="1.0" ixy="0.0" ixz="0.0" iyy="1.0" iyz="0.0" izz="1.0"/>
    </inertial>
    <inertial>
      <origin rpy="1.57075 0 -1.57075" xyz="-0.3554 -.075 -.0125"/>
      <mass value="0.01"/>
      <inertia ixx="1.0" ixy="0.0" ixz="0.0" iyy="1.0" iyz="0.0" izz="1.0"/>
    </inertial>
  </link>
  <joint name="shoulder_elbow/OUTPUT_JOINT" type="fixed">
    <parent link="shoulder_elbow/INPUT_INTERFACE"/>
    <child link="HEBI/elbow/INPUT_INTERFACE"/>
    <origin rpy="3.14157 0 0" xyz="-0.38 0 0"/>
  </joint>
  <gazebo reference="shoulder_elbow/INPUT_INTERFACE">
    <selfCollide>true</selfCollide>
  </gazebo>
  <link name="HEBI/elbow/INPUT_INTERFACE">
    <visual>
      <origin rpy="3.14157 0 0" xyz="0 0 0.0155"/>
      <geometry>
        <mesh filename="package://hebiros/meshes/x5.stl"/>
      </geometry>
      <material name="red">
        <color rgba=".82 0.06 0.06 1"/>
      </material>
    </visual>
    <collision>
      <origin rpy="3.14157 0 0" xyz="0 0 0.0155"/>
      <geometry>
        <mesh filename="package://hebiros/meshes/x5.stl"/>
      </geometry>
    </collision>
    <inertial>
      <origin rpy="3.14157 0 0" xyz="0 0 0.0155"/>
      <mass value="0.335"/>
      <inertia ixx="1.0" ixy="0.0" ixz="0.0" iyy="1.0" iyz="0.0" izz="1.0"/>
    </inertial>
  </link>
  <joint name="HEBI/elbow" type="revolute">
    <parent link="HEBI/elbow/INPUT_INTERFACE"/>
    <child link="elbow_end/INPUT_INTERFACE"/>
    <origin rpy="0 0 0" xyz="0 0 0.031"/>
    <axis xyz="0 0 1"/>
    <limit effort="9.0" lower="-10.0" upper="10.0" velocity="2.208932"/>
    <dynamics damping="0.2" friction="0.2"/>
  </joint>
  <transmission name="HEBI/elbow/transmission">
    <type>transmission_interface/SimpleTransmission</type>
    <joint name="HEBI/elbow">
      <hardwareInterface>hardware_interface/EffortJointInterface</hardwareInterface>
    </joint>
    <actuator name="HEBI/elbow/actuator">
      <hardwareInterface>hardware_interface/EffortJointInterface</hardwareInterface>
      <mechanicalReduction>1</mechanicalReduction>
    </actuator>
  </transmission>
  <gazebo reference="HEBI/elbow/INPUT_INTERFACE">
    <selfCollide>true</selfCollide>
  </gazebo>
  <link name="elbow_end/INPUT_INTERFACE">
    <visual>
      <origin rpy="0 0 3.14157" xyz="-.04 .03 .0075"/>
      <geometry>
        <mesh filename="package://hebiros/meshes/x_output_bracket.stl"/>
      </geometry>
      <material name="black">
        <color rgba="0 0 0 1"/>
      </material>
    </visual>
    <visual>
      <origin rpy="0 1.57075 0" xyz="-0.1879 0 .016075"/>
      <geometry>
        <cylinder length="0.325" radius=".015875"/>
      </geometry>
      <material name="silver">
        <color rgba="0.6 0.6 0.6 1"/>
      </material>
    </visual>
    <visual>
      <origin rpy="1.57075 0 -1.57075" xyz="-0.3504 -.075 -.0125"/>
      <geometry>
        <mesh filename="package://hebiros/meshes/x_mounting_bracket.stl"/>
      </geometry>
      <material name="black">
        <color rgba="0 0 0 1"/>
      </material>
    </visual>
    <collision>
      <origin rpy="0 0 3.14157" xyz="-.04 .03 .0075"/>
      <geometry>
        <mesh filename="package://hebiros/meshes/x_output_bracket.stl"/>
      </geometry>
    </collision>
    <collision>
      <origin rpy="0 1.57075 0" xyz="-0.1879 0 .016075"/>
      <geometry>
        <cylinder length="0.325" radius=".015875"/>
      </geometry>
    </collision>
    <collision>
      <origin rpy="1.57075 0 -1.57075" xyz="-0.3504 -.075 -.0125"/>
      <geometry>
        <mesh filename="package://hebiros/meshes/x_mounting_bracket.stl"/>
      </geometry>
    </collision>
    <inertial>
      <origin rpy="0 0 3.14157" xyz="-.04 .03 .0075"/>
      <mass value="0.01"/>
      <inertia ixx="1.0" ixy="0.0" ixz="0.0" iyy="1.0" iyz="0.0" izz="1.0"/>
    </inertial>
    <inertial>
      <origin rpy="0 1.57075 0" xyz="-0.1879 0 .016075"/>
      <mass value="0.375"/>
      <inertia ixx="1.0" ixy="0.0" ixz="0.0" iyy="1.0" iyz="0.0" izz="1.0"/>
    </inertial>
    <inertial>
      <origin rpy="1.57075 0 -1.57075" xyz="-0.3504 -.075 -.0125"/>
      <mass value="0.01"/>
      <inertia ixx="1.0" ixy="0.0" ixz="0.0" iyy="1.0" iyz="0.0" izz="1.0"/>
    </inertial>
  </link>
  <joint name="elbow_end/OUTPUT_JOINT" type="fixed">
    <parent link="elbow_end/INPUT_INTERFACE"/>
    <child link="end_effector/INPUT_INTERFACE"/>
    <origin rpy="3.14157 0 0" xyz="-0.375 0 0"/>
  </joint>
  <gazebo reference="elbow_end/INPUT_INTERFACE">
    <selfCollide>true</selfCollide>
  </gazebo>
  <!-- end link -->
  <link name="end_effector/INPUT_INTERFACE">
  </link>
  <gazebo reference="base">
    <selfCollide>true</selfCollide>
  </gazebo>
  <gazebo>
    <plugin filename="libgazebo_ros_control.so" name="gazebo_ros_control">
      <robotNamespace>/hebiros/x_demo</robotNamespace>
    </plugin>
  </gazebo>
</robot>

