<?xml version="1.0" ?>
<!-- =================================================================================== -->
<!-- |    This document was autogenerated by xacro from x_demo.xacro                   | -->
<!-- |    EDITING THIS FILE BY HAND IS NOT RECOMMENDED                                 | -->
<!-- =================================================================================== -->
<robot name="arm_demo" xmlns:xacro="http://www.ros.org/wiki/xacro">
  <!-- *************************** XACRO MACROS *************************** -->
  <!-- ************************* ROBOT DEFINITION ************************* -->
  <!-- just for visualization: base post -->
  <link name="base_link">
    <inertial>
      <origin xyz=".125 0 -0.254"/>
      <mass value="1.0"/>
      <inertia  ixx="1.0" ixy="0.0"  ixz="0.0"  iyy="0.0"  iyz="0.0"  izz="0.0"/>
    </inertial>
    <visual>
      <origin rpy="0 0 0" xyz=".125 0 -.0254"/>
      <geometry>
        <box size="0.25 0.5 0.0508"/>
      </geometry>
      <material name="silver">
        <color rgba="0.6 0.6 0.6 1"/>
      </material>
    </visual>
    <collision>
      <origin xyz="0 0 0"/>
      <geometry>
        <box size="1 1 1" />
      </geometry>
    </collision>
  </link>
  <joint name="base-base" type="fixed">
    <parent link="base_link"/>
    <child link="base|HEBI|INPUT_INTERFACE"/>
    <origin rpy="0 0 0" xyz="0 0 0"/>
  </joint>
  <link name="base|HEBI|INPUT_INTERFACE">
    <visual>
      <origin rpy="3.14157 0 0" xyz="0 0 0.0155"/>
      <geometry>
        <mesh filename="package://hebi/meshes/x5.stl"/>
      </geometry>
      <material name="red">
        <color rgba=".82 0.06 0.06 1"/>
      </material>
    </visual>
  </link>
  <joint name="base|HEBI" type="revolute">
    <parent link="base|HEBI|INPUT_INTERFACE"/>
    <child link="shoulder-bracket|INPUT_INTERFACE"/>
    <origin rpy="0 0 0" xyz="0 0 0.031"/>
    <axis xyz="0 0 1"/>
    <limit effort="1.5" lower="0.0" upper="1.0" velocity="2.208932"/>
  </joint>
  <link name="shoulder-bracket|INPUT_INTERFACE">
    <visual>
      <origin rpy="1.57075 0 1.57075" xyz="0 0 0"/>
      <geometry>
        <mesh filename="package://hebi/meshes/x_wrist.stl"/>
      </geometry>
      <material name="silver">
        <color rgba="0.6 0.6 0.6 1"/>
      </material>
    </visual>
  </link>
  <joint name="shoulder-bracket|OUTPUT_INTERFACE" type="fixed">
    <parent link="shoulder-bracket|INPUT_INTERFACE"/>
    <child link="shoulder|HEBI|INPUT_INTERFACE"/>
    <!--    <origin xyz="0 .03685 .05715" rpy="-1.57075 0 3.14157"/>-->
    <origin rpy="-1.57075 0 0" xyz="0 .04235 .05715"/>
  </joint>
  <link name="shoulder|HEBI|INPUT_INTERFACE">
    <visual>
      <origin rpy="3.14157 0 0" xyz="0 0 0.0155"/>
      <geometry>
        <mesh filename="package://hebi/meshes/x5.stl"/>
      </geometry>
      <material name="red">
        <color rgba=".82 0.06 0.06 1"/>
      </material>
    </visual>
  </link>
  <joint name="shoulder|HEBI" type="revolute">
    <parent link="shoulder|HEBI|INPUT_INTERFACE"/>
    <child link="shoulder-elbow|INPUT_INTERFACE"/>
    <origin rpy="0 0 0" xyz="0 0 0.031"/>
    <axis xyz="0 0 1"/>
    <limit effort="1.5" lower="0.0" upper="1.0" velocity="2.208932"/>
  </joint>
  <link name="shoulder-elbow|INPUT_INTERFACE">
    <visual>
      <origin rpy="0 0 3.14157" xyz="-.04 .03 .0075"/>
      <geometry>
        <mesh filename="package://hebi/meshes/x_output_bracket.stl"/>
      </geometry>
      <material name="black">
        <color rgba="0 0 0 1"/>
      </material>
    </visual>
    <visual>
      <origin rpy="0 1.57075 0" xyz="-0.1904 0 .016075"/>
      <geometry>
        <cylinder length="0.33" radius=".015875"/>
      </geometry>
      <material name="silver">
        <color rgba="0.6 0.6 0.6 1"/>
      </material>
    </visual>
    <visual>
      <origin rpy="1.57075 0 -1.57075" xyz="-0.3554 -.075 -.0125"/>
      <geometry>
        <mesh filename="package://hebi/meshes/x_mounting_bracket.stl"/>
      </geometry>
      <material name="black">
        <color rgba="0 0 0 1"/>
      </material>
    </visual>
  </link>
  <joint name="shoulder-elbow|OUTPUT_JOINT" type="fixed">
    <parent link="shoulder-elbow|INPUT_INTERFACE"/>
    <child link="elbow|HEBI|INPUT_INTERFACE"/>
    <origin rpy="3.14157 0 0" xyz="-0.38 0 0"/>
  </joint>
  <link name="elbow|HEBI|INPUT_INTERFACE">
    <visual>
      <origin rpy="3.14157 0 0" xyz="0 0 0.0155"/>
      <geometry>
        <mesh filename="package://hebi/meshes/x5.stl"/>
      </geometry>
      <material name="red">
        <color rgba=".82 0.06 0.06 1"/>
      </material>
    </visual>
  </link>
  <joint name="elbow|HEBI" type="revolute">
    <parent link="elbow|HEBI|INPUT_INTERFACE"/>
    <child link="elbow-end|INPUT_INTERFACE"/>
    <origin rpy="0 0 0" xyz="0 0 0.031"/>
    <axis xyz="0 0 1"/>
    <limit effort="1.5" lower="0.0" upper="1.0" velocity="2.208932"/>
  </joint>
  <link name="elbow-end|INPUT_INTERFACE">
    <visual>
      <origin rpy="0 0 3.14157" xyz="-.04 .03 .0075"/>
      <geometry>
        <mesh filename="package://hebi/meshes/x_output_bracket.stl"/>
      </geometry>
      <material name="black">
        <color rgba="0 0 0 1"/>
      </material>
    </visual>
    <visual>
      <origin rpy="0 1.57075 0" xyz="-0.1879 0 .016075"/>
      <geometry>
        <cylinder length="0.325" radius=".015875"/>
      </geometry>
      <material name="silver">
        <color rgba="0.6 0.6 0.6 1"/>
      </material>
    </visual>
    <visual>
      <origin rpy="1.57075 0 -1.57075" xyz="-0.3504 -.075 -.0125"/>
      <geometry>
        <mesh filename="package://hebi/meshes/x_mounting_bracket.stl"/>
      </geometry>
      <material name="black">
        <color rgba="0 0 0 1"/>
      </material>
    </visual>
  </link>
  <joint name="elbow-end|OUTPUT_JOINT" type="fixed">
    <parent link="elbow-end|INPUT_INTERFACE"/>
    <child link="end_effector|INPUT_INTERFACE"/>
    <origin rpy="3.14157 0 0" xyz="-0.375 0 0"/>
  </joint>
  <!-- test child...TODO CHANGE -->
  <link name="end_effector|INPUT_INTERFACE">
    <!--<visual>
      <origin xyz="0 0 0.023" rpy="0 0 0" />
      <geometry>
        <box size="0.0508 0.0508 0.0508" />
      </geometry>
      <xacro:silver_material/>
    </visual>-->
  </link>
</robot>

