<?xml version="1.0" ?>
<!-- =================================================================================== -->
<!-- |    This document was autogenerated by xacro from 3_dof_arm.xacro                | -->
<!-- |    EDITING THIS FILE BY HAND IS NOT RECOMMENDED                                 | -->
<!-- =================================================================================== -->
<robot name="3_dof_arm" xmlns:xacro="http://www.ros.org/wiki/xacro">
  <!-- *************************** XACRO MACROS *************************** -->
  <!-- ************************* ROBOT DEFINITION ************************* -->
  <!-- world link -->
  <link name="world"/>
  <joint name="world_joint" type="fixed">
    <origin rpy="0 0 0" xyz="0 0 0"/>
    <parent link="world"/>
    <child link="HEBI/joint1/INPUT_INTERFACE"/>
  </joint>
  <link name="HEBI/joint1/INPUT_INTERFACE">
    <visual>
      <origin rpy="0 0 0" xyz="0 0 0"/>
      <geometry>
        <mesh filename="package://hebiros_description/meshes/x5.stl" scale="0.001 0.001 0.001"/>
      </geometry>
      <material name="red">
        <color rgba=".82 0.06 0.06 1"/>
      </material>
    </visual>
    <collision>
      <origin rpy="0 0 0" xyz="0 0 0"/>
      <geometry>
        <mesh filename="package://hebiros_description/meshes/x5.stl" scale="0.001 0.001 0.001"/>
      </geometry>
    </collision>
    <inertial>
      <origin rpy="0 0 0" xyz="-0.0142 -0.0031 0.0165"/>
      <mass value="0.335"/>
      <inertia ixx="0.00015" ixy="0.0000341" ixz="0.0000118" iyy="0.000255" iyz="0.00000229" izz="0.000350"/>
    </inertial>
  </link>
  <joint name="HEBI/joint1/X5_4" type="continuous">
    <parent link="HEBI/joint1/INPUT_INTERFACE"/>
    <child link="joint1_joint2/INPUT_INTERFACE"/>
    <origin rpy="0 0 0" xyz="0 0 0.031"/>
    <axis xyz="0 0 1"/>
    <limit effort="7.0" velocity="32"/>
    <dynamics damping="0.1" friction="0.1"/>
  </joint>
  <gazebo reference="HEBI/joint1/INPUT_INTERFACE">
    <selfCollide>true</selfCollide>
    <gravity>true</gravity>
    <sensor name="HEBI/joint1/imu_sensor" type="imu">
      <always_on>true</always_on>
      <update_rate>100</update_rate>
      <visualize>true</visualize>
      <plugin filename="libgazebo_ros_imu_sensor.so" name="imu_plugin">
        <topicName>/hebiros_gazebo_plugin/imu/HEBI/joint1</topicName>
        <bodyName>HEBI/joint1/imu_link</bodyName>
        <updateRateHZ>10.0</updateRateHZ>
        <gaussianNoise>0.0</gaussianNoise>
        <xyzOffset>0.025 0 0.003</xyzOffset>
        <rpyOffset>0 0 0</rpyOffset>
        <frameName>HEBI/joint1/imu_link</frameName>
      </plugin>
      <pose>0 0 0 0 0 0</pose>
    </sensor>
    <material>Gazebo/BlueGlow</material>
  </gazebo>
  <link name="joint1_joint2/INPUT_INTERFACE">
    <visual>
      <origin rpy="1.57079632679 0 1.57079632679" xyz="0 0 0.005"/>
      <geometry>
        <mesh filename="package://hebiros_description/meshes/PM-2149-01.stl" scale="0.001 0.001 0.001"/>
      </geometry>
      <material name="black">
        <color rgba="0 0 0 1"/>
      </material>
    </visual>
    <visual>
      <origin rpy="1.57079632679 0 0" xyz="0 -.03 .04"/>
      <geometry>
        <mesh filename="package://hebiros_description/meshes/PM-2150-01R.stl" scale="0.001 0.001 0.001"/>
      </geometry>
      <material name="black">
        <color rgba="0 0 0 1"/>
      </material>
    </visual>
    <collision>
      <origin rpy="1.57079632679 0 1.57079632679" xyz="0 0 0.005"/>
      <geometry>
        <mesh filename="package://hebiros_description/meshes/PM-2149-01.stl" scale="0.001 0.001 0.001"/>
      </geometry>
    </collision>
    <collision>
      <origin rpy="1.57079632679 0 0" xyz="0 -.03 .04"/>
      <geometry>
        <mesh filename="package://hebiros_description/meshes/PM-2150-01R.stl" scale="0.001 0.001 0.001"/>
      </geometry>
    </collision>
    <!-- NOTE: inertia is just modelled as small sphere, and could be improved. -->
    <inertial>
      <origin rpy="0 0 0" xyz="0 -0.01875 .0275"/>
      <mass value="0.215"/>
      <inertia ixx="0.0003096" ixy="0.0" ixz="0.0" iyy="0.0003096" iyz="0.0" izz="0.0003096"/>
    </inertial>
  </link>
  <joint name="joint1_joint2/OUTPUT_INTERFACE" type="fixed">
    <parent link="joint1_joint2/INPUT_INTERFACE"/>
    <child link="HEBI/joint2/INPUT_INTERFACE"/>
    <origin rpy="1.57079632679 0 0" xyz="0 -.0375 .055"/>
  </joint>
  <gazebo reference="joint1_joint2/INPUT_INTERFACE">
    <selfCollide>true</selfCollide>
  </gazebo>
  <link name="HEBI/joint2/INPUT_INTERFACE">
    <visual>
      <origin rpy="0 0 0" xyz="0 0 0"/>
      <geometry>
        <mesh filename="package://hebiros_description/meshes/x5.stl" scale="0.001 0.001 0.001"/>
      </geometry>
      <material name="red">
        <color rgba=".82 0.06 0.06 1"/>
      </material>
    </visual>
    <collision>
      <origin rpy="0 0 0" xyz="0 0 0"/>
      <geometry>
        <mesh filename="package://hebiros_description/meshes/x5.stl" scale="0.001 0.001 0.001"/>
      </geometry>
    </collision>
    <inertial>
      <origin rpy="0 0 0" xyz="-0.0142 -0.0031 0.0165"/>
      <mass value="0.335"/>
      <inertia ixx="0.00015" ixy="0.0000341" ixz="0.0000118" iyy="0.000255" iyz="0.00000229" izz="0.000350"/>
    </inertial>
  </link>
  <joint name="HEBI/joint2/X5_4" type="continuous">
    <parent link="HEBI/joint2/INPUT_INTERFACE"/>
    <child link="joint2_joint3/INPUT_INTERFACE"/>
    <origin rpy="0 0 0" xyz="0 0 0.031"/>
    <axis xyz="0 0 1"/>
    <limit effort="7.0" velocity="32"/>
    <dynamics damping="0.1" friction="0.1"/>
  </joint>
  <gazebo reference="HEBI/joint2/INPUT_INTERFACE">
    <selfCollide>true</selfCollide>
    <gravity>true</gravity>
    <sensor name="HEBI/joint2/imu_sensor" type="imu">
      <always_on>true</always_on>
      <update_rate>100</update_rate>
      <visualize>true</visualize>
      <plugin filename="libgazebo_ros_imu_sensor.so" name="imu_plugin">
        <topicName>/hebiros_gazebo_plugin/imu/HEBI/joint2</topicName>
        <bodyName>HEBI/joint2/imu_link</bodyName>
        <updateRateHZ>10.0</updateRateHZ>
        <gaussianNoise>0.0</gaussianNoise>
        <xyzOffset>0.025 0 0.003</xyzOffset>
        <rpyOffset>0 0 0</rpyOffset>
        <frameName>HEBI/joint2/imu_link</frameName>
      </plugin>
      <pose>0 0 0 0 0 0</pose>
    </sensor>
    <material>Gazebo/BlueGlow</material>
  </gazebo>
  <link name="joint2_joint3/INPUT_INTERFACE">
    <visual>
      <origin rpy="0 0 0" xyz="0 0 0"/>
      <geometry>
        <mesh filename="package://hebiros_description/meshes/A-2038-02.stl"/>
      </geometry>
      <material name="black">
        <color rgba="0 0 0 1"/>
      </material>
    </visual>
    <visual>
      <origin rpy="0 1.57075 0" xyz="0.15 0 0.02"/>
      <geometry>
        <cylinder length="0.2746" radius=".016"/>
      </geometry>
      <material name="silver">
        <color rgba="0.6 0.6 0.6 1"/>
      </material>
    </visual>
    <visual>
      <origin rpy="-3.14159265359 0 0" xyz="0.3 -2.44929359829e-18 0.0"/>
      <geometry>
        <mesh filename="package://hebiros_description/meshes/A-2039-02.stl"/>
      </geometry>
      <material name="black">
        <color rgba="0 0 0 1"/>
      </material>
    </visual>
    <collision>
      <origin rpy="0 0 0" xyz="0 0 0"/>
      <geometry>
        <mesh filename="package://hebiros_description/meshes/A-2038-02.stl"/>
      </geometry>
    </collision>
    <collision>
      <origin rpy="0 1.57075 0" xyz="0.15 0 0.02"/>
      <geometry>
        <cylinder length="0.2746" radius=".016"/>
      </geometry>
    </collision>
    <collision>
      <origin rpy="-3.14159265359 0 0" xyz="0.3 -2.44929359829e-18 0.0"/>
      <geometry>
        <mesh filename="package://hebiros_description/meshes/A-2039-02.stl"/>
      </geometry>
    </collision>
    <!-- Approximate inertia as thin rod about x axis -->
    <inertial>
      <origin rpy="0 0 0" xyz="0.15 0 0.02"/>
      <mass value="0.392"/>
      <inertia ixx="0.0" ixy="0.0" ixz="0.0" iyy="0.00294" iyz="0.0" izz="0.00294"/>
    </inertial>
  </link>
  <joint name="joint2_joint3/OUTPUT_JOINT" type="fixed">
    <parent link="joint2_joint3/INPUT_INTERFACE"/>
    <child link="HEBI/joint3/INPUT_INTERFACE"/>
    <origin rpy="3.14159265359 0 0" xyz="0.3 -2.44929359829e-18 0.0"/>
  </joint>
  <gazebo reference="joint2_joint3/INPUT_INTERFACE">
    <selfCollide>true</selfCollide>
    <material>Gazebo/FlatBlack</material>
  </gazebo>
  <link name="HEBI/joint3/INPUT_INTERFACE">
    <visual>
      <origin rpy="0 0 0" xyz="0 0 0"/>
      <geometry>
        <mesh filename="package://hebiros_description/meshes/x5.stl" scale="0.001 0.001 0.001"/>
      </geometry>
      <material name="red">
        <color rgba=".82 0.06 0.06 1"/>
      </material>
    </visual>
    <collision>
      <origin rpy="0 0 0" xyz="0 0 0"/>
      <geometry>
        <mesh filename="package://hebiros_description/meshes/x5.stl" scale="0.001 0.001 0.001"/>
      </geometry>
    </collision>
    <inertial>
      <origin rpy="0 0 0" xyz="-0.0142 -0.0031 0.0165"/>
      <mass value="0.335"/>
      <inertia ixx="0.00015" ixy="0.0000341" ixz="0.0000118" iyy="0.000255" iyz="0.00000229" izz="0.000350"/>
    </inertial>
  </link>
  <joint name="HEBI/joint3/X5_4" type="continuous">
    <parent link="HEBI/joint3/INPUT_INTERFACE"/>
    <child link="joint3_end/INPUT_INTERFACE"/>
    <origin rpy="0 0 0" xyz="0 0 0.031"/>
    <axis xyz="0 0 1"/>
    <limit effort="7.0" velocity="32"/>
    <dynamics damping="0.1" friction="0.1"/>
  </joint>
  <gazebo reference="HEBI/joint3/INPUT_INTERFACE">
    <selfCollide>true</selfCollide>
    <gravity>true</gravity>
    <sensor name="HEBI/joint3/imu_sensor" type="imu">
      <always_on>true</always_on>
      <update_rate>100</update_rate>
      <visualize>true</visualize>
      <plugin filename="libgazebo_ros_imu_sensor.so" name="imu_plugin">
        <topicName>/hebiros_gazebo_plugin/imu/HEBI/joint3</topicName>
        <bodyName>HEBI/joint3/imu_link</bodyName>
        <updateRateHZ>10.0</updateRateHZ>
        <gaussianNoise>0.0</gaussianNoise>
        <xyzOffset>0.025 0 0.003</xyzOffset>
        <rpyOffset>0 0 0</rpyOffset>
        <frameName>HEBI/joint3/imu_link</frameName>
      </plugin>
      <pose>0 0 0 0 0 0</pose>
    </sensor>
    <material>Gazebo/BlueGlow</material>
  </gazebo>
  <link name="joint3_end/INPUT_INTERFACE">
    <visual>
      <origin rpy="0 0 0" xyz="0 0 0"/>
      <geometry>
        <mesh filename="package://hebiros_description/meshes/A-2038-02.stl"/>
      </geometry>
      <material name="black">
        <color rgba="0 0 0 1"/>
      </material>
    </visual>
    <visual>
      <origin rpy="0 1.57075 0" xyz="0.15 0 0.02"/>
      <geometry>
        <cylinder length="0.2746" radius=".016"/>
      </geometry>
      <material name="silver">
        <color rgba="0.6 0.6 0.6 1"/>
      </material>
    </visual>
    <visual>
      <origin rpy="-3.14159265359 0 0" xyz="0.3 -2.44929359829e-18 0.0"/>
      <geometry>
        <mesh filename="package://hebiros_description/meshes/A-2039-02.stl"/>
      </geometry>
      <material name="black">
        <color rgba="0 0 0 1"/>
      </material>
    </visual>
    <collision>
      <origin rpy="0 0 0" xyz="0 0 0"/>
      <geometry>
        <mesh filename="package://hebiros_description/meshes/A-2038-02.stl"/>
      </geometry>
    </collision>
    <collision>
      <origin rpy="0 1.57075 0" xyz="0.15 0 0.02"/>
      <geometry>
        <cylinder length="0.2746" radius=".016"/>
      </geometry>
    </collision>
    <collision>
      <origin rpy="-3.14159265359 0 0" xyz="0.3 -2.44929359829e-18 0.0"/>
      <geometry>
        <mesh filename="package://hebiros_description/meshes/A-2039-02.stl"/>
      </geometry>
    </collision>
    <!-- Approximate inertia as thin rod about x axis -->
    <inertial>
      <origin rpy="0 0 0" xyz="0.15 0 0.02"/>
      <mass value="0.392"/>
      <inertia ixx="0.0" ixy="0.0" ixz="0.0" iyy="0.00294" iyz="0.0" izz="0.00294"/>
    </inertial>
  </link>
  <joint name="joint3_end/OUTPUT_JOINT" type="fixed">
    <parent link="joint3_end/INPUT_INTERFACE"/>
    <child link="end_effector/INPUT_INTERFACE"/>
    <origin rpy="3.14159265359 0 0" xyz="0.3 -2.44929359829e-18 0.0"/>
  </joint>
  <gazebo reference="joint3_end/INPUT_INTERFACE">
    <selfCollide>true</selfCollide>
    <material>Gazebo/FlatBlack</material>
  </gazebo>
  <!-- end link -->
  <link name="end_effector/INPUT_INTERFACE">
  </link>
  <gazebo>
    <plugin filename="libhebiros_gazebo_plugin.so" name="hebiros_gazebo_plugin">
    </plugin>
  </gazebo>
</robot>

