<?xml version="1.0" ?>
<!-- =================================================================================== -->
<!-- |    This document was autogenerated by xacro from A-2085-06.xacro                | -->
<!-- |    EDITING THIS FILE BY HAND IS NOT RECOMMENDED                                 | -->
<!-- =================================================================================== -->
<robot name="A-2085-06" xmlns:xacro="http://www.ros.org/wiki/xacro">
  <!-- *************************** XACRO MACROS *************************** -->
  <!-- ************************* ROBOT DEFINITION ************************* -->
  <link name="world"/>
  <joint name="world_joint" type="fixed">
    <origin rpy="0 0 0" xyz="0 0 0"/>
    <parent link="world"/>
    <child link="base"/>
  </joint>
  <!-- just for visualization: base post -->
  <link name="base">
    <visual>
      <origin rpy="0 0 0" xyz="-.125 0 -.0254"/>
      <geometry>
        <box size="0.25 0.5 0.0508"/>
      </geometry>
      <material name="silver">
        <color rgba="0.6 0.6 0.6 1"/>
      </material>
    </visual>
    <collision>
      <origin rpy="0 0 0" xyz="-.125 0 -.0254"/>
      <geometry>
        <box size="0.25 0.5 0.0508"/>
      </geometry>
    </collision>
    <inertial>
      <origin rpy="0 0 0" xyz=".125 0 -.0254"/>
      <mass value="1.0"/>
      <inertia ixx="1.0" ixy="0.0" ixz="0.0" iyy="1.0" iyz="0.0" izz="1.0"/>
    </inertial>
  </link>
  <joint name="base_base" type="fixed">
    <parent link="base"/>
    <child link="HEBI/base/INPUT_INTERFACE"/>
    <origin rpy="0 0 0" xyz="0 0 0"/>
  </joint>
  <link name="HEBI/base/INPUT_INTERFACE">
    <visual>
      <origin rpy="0 0 0" xyz="0 0 0"/>
      <geometry>
        <mesh filename="package://hebiros_description/meshes/x8.stl" scale="0.001 0.001 0.001"/>
      </geometry>
      <material name="red">
        <color rgba=".82 0.06 0.06 1"/>
      </material>
    </visual>
    <collision>
      <origin rpy="0 0 0" xyz="0 0 0"/>
      <geometry>
        <mesh filename="package://hebiros_description/meshes/x8.stl" scale="0.001 0.001 0.001"/>
      </geometry>
    </collision>
    <inertial>
      <origin rpy="0 0 0" xyz="-0.0145 -0.0031 0.0242"/>
      <mass value="0.480"/>
      <inertia ixx="0.000246" ixy="0.0000444" ixz="0.0000266" iyy="0.000380" iyz="0.00000422" izz="0.000463"/>
    </inertial>
  </link>
  <joint name="HEBI/base/X8_9" type="continuous">
    <parent link="HEBI/base/INPUT_INTERFACE"/>
    <child link="shoulder_bracket/INPUT_INTERFACE"/>
    <origin rpy="0 0 0" xyz="0 0 0.045"/>
    <axis xyz="0 0 1"/>
    <limit effort="20" velocity="30"/>
    <dynamics damping="0.5" friction="0.5"/>
  </joint>
  <transmission name="HEBI/base/transmission">
    <type>transmission_interface/SimpleTransmission</type>
    <joint name="HEBI/base">
      <hardwareInterface>hardware_interface/EffortJointInterface</hardwareInterface>
    </joint>
    <actuator name="HEBI/base/actuator">
      <hardwareInterface>hardware_interface/EffortJointInterface</hardwareInterface>
      <mechanicalReduction>1</mechanicalReduction>
    </actuator>
  </transmission>
  <gazebo reference="HEBI/base/INPUT_INTERFACE">
    <selfCollide>true</selfCollide>
    <gravity>true</gravity>
    <sensor name="HEBI/base/imu_sensor" type="imu">
      <always_on>true</always_on>
      <update_rate>100</update_rate>
      <visualize>true</visualize>
      <plugin filename="libgazebo_ros_imu_sensor.so" name="imu_plugin">
        <topicName>/hebiros_gazebo_plugin/imu/HEBI/base</topicName>
        <bodyName>HEBI/base/imu_link</bodyName>
        <updateRateHZ>10.0</updateRateHZ>
        <gaussianNoise>0.0</gaussianNoise>
        <xyzOffset>0.025 0 0.003</xyzOffset>
        <rpyOffset>0 0 0</rpyOffset>
        <frameName>HEBI/base/imu_link</frameName>
      </plugin>
      <pose>0 0 0 0 0 0</pose>
    </sensor>
  </gazebo>
  <link name="shoulder_bracket/INPUT_INTERFACE">
    <visual>
      <origin rpy="1.57079632679 0 1.57079632679" xyz="0 0 0.005"/>
      <geometry>
        <mesh filename="package://hebiros_description/meshes/PM-2149-01.stl" scale="0.001 0.001 0.001"/>
      </geometry>
      <material name="black">
        <color rgba="0 0 0 1"/>
      </material>
    </visual>
    <visual>
      <origin rpy="1.57079632679 0 0" xyz="0 -.03 .04"/>
      <geometry>
        <mesh filename="package://hebiros_description/meshes/PM-2150-01R.stl" scale="0.001 0.001 0.001"/>
      </geometry>
      <material name="black">
        <color rgba="0 0 0 1"/>
      </material>
    </visual>
    <collision>
      <origin rpy="1.57079632679 0 1.57079632679" xyz="0 0 0.005"/>
      <geometry>
        <mesh filename="package://hebiros_description/meshes/PM-2149-01.stl" scale="0.001 0.001 0.001"/>
      </geometry>
    </collision>
    <collision>
      <origin rpy="1.57079632679 0 0" xyz="0 -.03 .04"/>
      <geometry>
        <mesh filename="package://hebiros_description/meshes/PM-2150-01R.stl" scale="0.001 0.001 0.001"/>
      </geometry>
    </collision>
    <!-- NOTE: inertia is just modelled as small sphere, and could be improved. -->
    <inertial>
      <origin rpy="0 0 0" xyz="0 -0.01875 .0275"/>
      <mass value="0.215"/>
      <inertia ixx="0.0003096" ixy="0.0" ixz="0.0" iyy="0.0003096" iyz="0.0" izz="0.0003096"/>
    </inertial>
  </link>
  <joint name="shoulder_bracket/OUTPUT_INTERFACE" type="fixed">
    <parent link="shoulder_bracket/INPUT_INTERFACE"/>
    <child link="HEBI/shoulder/INPUT_INTERFACE"/>
    <origin rpy="1.57079632679 0 0" xyz="0 -.0375 .055"/>
  </joint>
  <gazebo reference="shoulder_bracket/INPUT_INTERFACE">
    <selfCollide>true</selfCollide>
  </gazebo>
  <link name="HEBI/shoulder/INPUT_INTERFACE">
    <visual>
      <origin rpy="0 0 0" xyz="0 0 0"/>
      <geometry>
        <mesh filename="package://hebiros_description/meshes/x8.stl" scale="0.001 0.001 0.001"/>
      </geometry>
      <material name="red">
        <color rgba=".82 0.06 0.06 1"/>
      </material>
    </visual>
    <collision>
      <origin rpy="0 0 0" xyz="0 0 0"/>
      <geometry>
        <mesh filename="package://hebiros_description/meshes/x8.stl" scale="0.001 0.001 0.001"/>
      </geometry>
    </collision>
    <inertial>
      <origin rpy="0 0 0" xyz="-0.0145 -0.0031 0.0242"/>
      <mass value="0.500"/>
      <inertia ixx="0.000246" ixy="0.0000444" ixz="0.0000266" iyy="0.000380" iyz="0.00000422" izz="0.000463"/>
    </inertial>
  </link>
  <joint name="HEBI/shoulder/X8_16" type="continuous">
    <parent link="HEBI/shoulder/INPUT_INTERFACE"/>
    <child link="shoulder_elbow/INPUT_INTERFACE"/>
    <origin rpy="0 0 0" xyz="0 0 0.045"/>
    <axis xyz="0 0 1"/>
    <limit effort="38" velocity="15"/>
    <dynamics damping="0.5" friction="0.5"/>
  </joint>
  <transmission name="HEBI/shoulder/transmission">
    <type>transmission_interface/SimpleTransmission</type>
    <joint name="HEBI/shoulder">
      <hardwareInterface>hardware_interface/EffortJointInterface</hardwareInterface>
    </joint>
    <actuator name="HEBI/shoulder/actuator">
      <hardwareInterface>hardware_interface/EffortJointInterface</hardwareInterface>
      <mechanicalReduction>1</mechanicalReduction>
    </actuator>
  </transmission>
  <gazebo reference="HEBI/shoulder/INPUT_INTERFACE">
    <selfCollide>true</selfCollide>
    <gravity>true</gravity>
    <sensor name="HEBI/shoulder/imu_sensor" type="imu">
      <always_on>true</always_on>
      <update_rate>100</update_rate>
      <visualize>true</visualize>
      <plugin filename="libgazebo_ros_imu_sensor.so" name="imu_plugin">
        <topicName>/hebiros_gazebo_plugin/imu/HEBI/shoulder</topicName>
        <bodyName>HEBI/shoulder/imu_link</bodyName>
        <updateRateHZ>10.0</updateRateHZ>
        <gaussianNoise>0.0</gaussianNoise>
        <xyzOffset>0.025 0 0.003</xyzOffset>
        <rpyOffset>0 0 0</rpyOffset>
        <frameName>HEBI/shoulder/imu_link</frameName>
      </plugin>
      <pose>0 0 0 0 0 0</pose>
    </sensor>
  </gazebo>
  <link name="shoulder_elbow/INPUT_INTERFACE">
    <visual>
      <origin rpy="0 0 0" xyz="0 0 0"/>
      <geometry>
        <mesh filename="package://hebiros_description/meshes/A-2038-02.stl"/>
      </geometry>
      <material name="black">
        <color rgba="0 0 0 1"/>
      </material>
    </visual>
    <visual>
      <origin rpy="0 1.57075 0" xyz="0.1625 0 0.02"/>
      <geometry>
        <cylinder length="0.2996" radius=".016"/>
      </geometry>
      <material name="silver">
        <color rgba="0.6 0.6 0.6 1"/>
      </material>
    </visual>
    <visual>
      <origin rpy="-3.14159265359 0 0" xyz="0.325 -2.44929359829e-18 0.0"/>
      <geometry>
        <mesh filename="package://hebiros_description/meshes/A-2039-02.stl"/>
      </geometry>
      <material name="black">
        <color rgba="0 0 0 1"/>
      </material>
    </visual>
    <collision>
      <origin rpy="0 0 0" xyz="0 0 0"/>
      <geometry>
        <mesh filename="package://hebiros_description/meshes/A-2038-02.stl"/>
      </geometry>
    </collision>
    <collision>
      <origin rpy="0 1.57075 0" xyz="0.1625 0 0.02"/>
      <geometry>
        <cylinder length="0.2996" radius=".016"/>
      </geometry>
    </collision>
    <collision>
      <origin rpy="-3.14159265359 0 0" xyz="0.325 -2.44929359829e-18 0.0"/>
      <geometry>
        <mesh filename="package://hebiros_description/meshes/A-2039-02.stl"/>
      </geometry>
    </collision>
    <!-- Approximate inertia as thin rod about x axis -->
    <inertial>
      <origin rpy="0 0 0" xyz="0.1625 0 0.02"/>
      <mass value="0.402"/>
      <inertia ixx="0.0" ixy="0.0" ixz="0.0" iyy="0.0035384375" iyz="0.0" izz="0.0035384375"/>
    </inertial>
  </link>
  <joint name="shoulder_elbow/OUTPUT_JOINT" type="fixed">
    <parent link="shoulder_elbow/INPUT_INTERFACE"/>
    <child link="HEBI/elbow/INPUT_INTERFACE"/>
    <origin rpy="3.14159265359 0 0" xyz="0.325 -2.44929359829e-18 0.0"/>
  </joint>
  <gazebo reference="shoulder_elbow/INPUT_INTERFACE">
    <selfCollide>true</selfCollide>
  </gazebo>
  <link name="HEBI/elbow/INPUT_INTERFACE">
    <visual>
      <origin rpy="0 0 0" xyz="0 0 0"/>
      <geometry>
        <mesh filename="package://hebiros_description/meshes/x8.stl" scale="0.001 0.001 0.001"/>
      </geometry>
      <material name="red">
        <color rgba=".82 0.06 0.06 1"/>
      </material>
    </visual>
    <collision>
      <origin rpy="0 0 0" xyz="0 0 0"/>
      <geometry>
        <mesh filename="package://hebiros_description/meshes/x8.stl" scale="0.001 0.001 0.001"/>
      </geometry>
    </collision>
    <inertial>
      <origin rpy="0 0 0" xyz="-0.0145 -0.0031 0.0242"/>
      <mass value="0.480"/>
      <inertia ixx="0.000246" ixy="0.0000444" ixz="0.0000266" iyy="0.000380" iyz="0.00000422" izz="0.000463"/>
    </inertial>
  </link>
  <joint name="HEBI/elbow/X8_9" type="continuous">
    <parent link="HEBI/elbow/INPUT_INTERFACE"/>
    <child link="elbow_wrist1/INPUT_INTERFACE"/>
    <origin rpy="0 0 0" xyz="0 0 0.045"/>
    <axis xyz="0 0 1"/>
    <limit effort="20" velocity="30"/>
    <dynamics damping="0.5" friction="0.5"/>
  </joint>
  <transmission name="HEBI/elbow/transmission">
    <type>transmission_interface/SimpleTransmission</type>
    <joint name="HEBI/elbow">
      <hardwareInterface>hardware_interface/EffortJointInterface</hardwareInterface>
    </joint>
    <actuator name="HEBI/elbow/actuator">
      <hardwareInterface>hardware_interface/EffortJointInterface</hardwareInterface>
      <mechanicalReduction>1</mechanicalReduction>
    </actuator>
  </transmission>
  <gazebo reference="HEBI/elbow/INPUT_INTERFACE">
    <selfCollide>true</selfCollide>
    <gravity>true</gravity>
    <sensor name="HEBI/elbow/imu_sensor" type="imu">
      <always_on>true</always_on>
      <update_rate>100</update_rate>
      <visualize>true</visualize>
      <plugin filename="libgazebo_ros_imu_sensor.so" name="imu_plugin">
        <topicName>/hebiros_gazebo_plugin/imu/HEBI/elbow</topicName>
        <bodyName>HEBI/elbow/imu_link</bodyName>
        <updateRateHZ>10.0</updateRateHZ>
        <gaussianNoise>0.0</gaussianNoise>
        <xyzOffset>0.025 0 0.003</xyzOffset>
        <rpyOffset>0 0 0</rpyOffset>
        <frameName>HEBI/elbow/imu_link</frameName>
      </plugin>
      <pose>0 0 0 0 0 0</pose>
    </sensor>
  </gazebo>
  <link name="elbow_wrist1/INPUT_INTERFACE">
    <visual>
      <origin rpy="0 0 0" xyz="0 0 0"/>
      <geometry>
        <mesh filename="package://hebiros_description/meshes/A-2038-02.stl"/>
      </geometry>
      <material name="black">
        <color rgba="0 0 0 1"/>
      </material>
    </visual>
    <visual>
      <origin rpy="0 1.57075 0" xyz="0.1625 0 0.02"/>
      <geometry>
        <cylinder length="0.2996" radius=".016"/>
      </geometry>
      <material name="silver">
        <color rgba="0.6 0.6 0.6 1"/>
      </material>
    </visual>
    <visual>
      <origin rpy="-3.14159265359 0 0" xyz="0.325 -2.44929359829e-18 0.0"/>
      <geometry>
        <mesh filename="package://hebiros_description/meshes/A-2039-02.stl"/>
      </geometry>
      <material name="black">
        <color rgba="0 0 0 1"/>
      </material>
    </visual>
    <collision>
      <origin rpy="0 0 0" xyz="0 0 0"/>
      <geometry>
        <mesh filename="package://hebiros_description/meshes/A-2038-02.stl"/>
      </geometry>
    </collision>
    <collision>
      <origin rpy="0 1.57075 0" xyz="0.1625 0 0.02"/>
      <geometry>
        <cylinder length="0.2996" radius=".016"/>
      </geometry>
    </collision>
    <collision>
      <origin rpy="-3.14159265359 0 0" xyz="0.325 -2.44929359829e-18 0.0"/>
      <geometry>
        <mesh filename="package://hebiros_description/meshes/A-2039-02.stl"/>
      </geometry>
    </collision>
    <!-- Approximate inertia as thin rod about x axis -->
    <inertial>
      <origin rpy="0 0 0" xyz="0.1625 0 0.02"/>
      <mass value="0.402"/>
      <inertia ixx="0.0" ixy="0.0" ixz="0.0" iyy="0.0035384375" iyz="0.0" izz="0.0035384375"/>
    </inertial>
  </link>
  <joint name="elbow_wrist1/OUTPUT_JOINT" type="fixed">
    <parent link="elbow_wrist1/INPUT_INTERFACE"/>
    <child link="HEBI/wrist1/INPUT_INTERFACE"/>
    <origin rpy="3.14159265359 0 0" xyz="0.325 -2.44929359829e-18 0.0"/>
  </joint>
  <gazebo reference="elbow_wrist1/INPUT_INTERFACE">
    <selfCollide>true</selfCollide>
  </gazebo>
  <link name="HEBI/wrist1/INPUT_INTERFACE">
    <visual>
      <origin rpy="0 0 0" xyz="0 0 0"/>
      <geometry>
        <mesh filename="package://hebiros_description/meshes/x5.stl" scale="0.001 0.001 0.001"/>
      </geometry>
      <material name="red">
        <color rgba=".82 0.06 0.06 1"/>
      </material>
    </visual>
    <collision>
      <origin rpy="0 0 0" xyz="0 0 0"/>
      <geometry>
        <mesh filename="package://hebiros_description/meshes/x5.stl" scale="0.001 0.001 0.001"/>
      </geometry>
    </collision>
    <inertial>
      <origin rpy="0 0 0" xyz="-0.0142 -0.0031 0.0165"/>
      <mass value="0.315"/>
      <inertia ixx="0.00015" ixy="0.0000341" ixz="0.0000118" iyy="0.000255" iyz="0.00000229" izz="0.000350"/>
    </inertial>
  </link>
  <joint name="HEBI/wrist1/X5_1" type="continuous">
    <parent link="HEBI/wrist1/INPUT_INTERFACE"/>
    <child link="wrist1_wrist2/INPUT_INTERFACE"/>
    <origin rpy="0 0 0" xyz="0 0 0.031"/>
    <axis xyz="0 0 1"/>
    <limit effort="2.5" velocity="90"/>
    <dynamics damping="0.1" friction="0.1"/>
  </joint>
  <gazebo reference="HEBI/wrist1/INPUT_INTERFACE">
    <selfCollide>true</selfCollide>
    <gravity>true</gravity>
    <sensor name="HEBI/wrist1/imu_sensor" type="imu">
      <always_on>true</always_on>
      <update_rate>100</update_rate>
      <visualize>true</visualize>
      <plugin filename="libgazebo_ros_imu_sensor.so" name="imu_plugin">
        <topicName>/hebiros_gazebo_plugin/imu/HEBI/wrist1</topicName>
        <bodyName>HEBI/wrist1/imu_link</bodyName>
        <updateRateHZ>10.0</updateRateHZ>
        <gaussianNoise>0.0</gaussianNoise>
        <xyzOffset>0.025 0 0.003</xyzOffset>
        <rpyOffset>0 0 0</rpyOffset>
        <frameName>HEBI/wrist1/imu_link</frameName>
      </plugin>
      <pose>0 0 0 0 0 0</pose>
    </sensor>
  </gazebo>
  <link name="wrist1_wrist2/INPUT_INTERFACE">
    <visual>
      <origin rpy="1.57079632679 0 -1.57079632679" xyz="0 0 0"/>
      <geometry>
        <mesh filename="package://hebiros_description/meshes/PM-2132-01R.stl" scale="0.001 0.001 0.001"/>
      </geometry>
      <material name="beige">
        <color rgba="0.96 0.945 0.871 1"/>
      </material>
    </visual>
    <collision>
      <origin rpy="1.57079632679 0 -1.57079632679" xyz="0 0 0"/>
      <geometry>
        <mesh filename="package://hebiros_description/meshes/PM-2132-01R.stl" scale="0.001 0.001 0.001"/>
      </geometry>
    </collision>
    <!-- NOTE: inertia is just modelled as small sphere, and could be improved. -->
    <inertial>
      <origin rpy="0 0 0" xyz="0 -.0215 .02"/>
      <mass value="0.1"/>
      <inertia ixx="0.000144" ixy="0.0" ixz="0.0" iyy="0.000144" iyz="0.0" izz="0.000144"/>
    </inertial>
  </link>
  <joint name="wrist1_wrist2/OUTPUT_INTERFACE" type="fixed">
    <parent link="wrist1_wrist2/INPUT_INTERFACE"/>
    <child link="HEBI/wrist2/INPUT_INTERFACE"/>
    <origin rpy="1.57079632679 0 0" xyz="0 -.043 .04"/>
  </joint>
  <gazebo reference="wrist1_wrist2/INPUT_INTERFACE">
    <selfCollide>true</selfCollide>
  </gazebo>
  <link name="HEBI/wrist2/INPUT_INTERFACE">
    <visual>
      <origin rpy="0 0 0" xyz="0 0 0"/>
      <geometry>
        <mesh filename="package://hebiros_description/meshes/x5.stl" scale="0.001 0.001 0.001"/>
      </geometry>
      <material name="red">
        <color rgba=".82 0.06 0.06 1"/>
      </material>
    </visual>
    <collision>
      <origin rpy="0 0 0" xyz="0 0 0"/>
      <geometry>
        <mesh filename="package://hebiros_description/meshes/x5.stl" scale="0.001 0.001 0.001"/>
      </geometry>
    </collision>
    <inertial>
      <origin rpy="0 0 0" xyz="-0.0142 -0.0031 0.0165"/>
      <mass value="0.315"/>
      <inertia ixx="0.00015" ixy="0.0000341" ixz="0.0000118" iyy="0.000255" iyz="0.00000229" izz="0.000350"/>
    </inertial>
  </link>
  <joint name="HEBI/wrist2/X5_1" type="continuous">
    <parent link="HEBI/wrist2/INPUT_INTERFACE"/>
    <child link="wrist2_wrist3/INPUT_INTERFACE"/>
    <origin rpy="0 0 0" xyz="0 0 0.031"/>
    <axis xyz="0 0 1"/>
    <limit effort="2.5" velocity="90"/>
    <dynamics damping="0.1" friction="0.1"/>
  </joint>
  <gazebo reference="HEBI/wrist2/INPUT_INTERFACE">
    <selfCollide>true</selfCollide>
    <gravity>true</gravity>
    <sensor name="HEBI/wrist2/imu_sensor" type="imu">
      <always_on>true</always_on>
      <update_rate>100</update_rate>
      <visualize>true</visualize>
      <plugin filename="libgazebo_ros_imu_sensor.so" name="imu_plugin">
        <topicName>/hebiros_gazebo_plugin/imu/HEBI/wrist2</topicName>
        <bodyName>HEBI/wrist2/imu_link</bodyName>
        <updateRateHZ>10.0</updateRateHZ>
        <gaussianNoise>0.0</gaussianNoise>
        <xyzOffset>0.025 0 0.003</xyzOffset>
        <rpyOffset>0 0 0</rpyOffset>
        <frameName>HEBI/wrist2/imu_link</frameName>
      </plugin>
      <pose>0 0 0 0 0 0</pose>
    </sensor>
  </gazebo>
  <link name="wrist2_wrist3/INPUT_INTERFACE">
    <visual>
      <origin rpy="1.57079632679 0 -1.57079632679" xyz="0 0 0"/>
      <geometry>
        <mesh filename="package://hebiros_description/meshes/PM-2132-01R.stl" scale="0.001 0.001 0.001"/>
      </geometry>
      <material name="beige">
        <color rgba="0.96 0.945 0.871 1"/>
      </material>
    </visual>
    <collision>
      <origin rpy="1.57079632679 0 -1.57079632679" xyz="0 0 0"/>
      <geometry>
        <mesh filename="package://hebiros_description/meshes/PM-2132-01R.stl" scale="0.001 0.001 0.001"/>
      </geometry>
    </collision>
    <!-- NOTE: inertia is just modelled as small sphere, and could be improved. -->
    <inertial>
      <origin rpy="0 0 0" xyz="0 -.0215 .02"/>
      <mass value="0.1"/>
      <inertia ixx="0.000144" ixy="0.0" ixz="0.0" iyy="0.000144" iyz="0.0" izz="0.000144"/>
    </inertial>
  </link>
  <joint name="wrist2_wrist3/OUTPUT_INTERFACE" type="fixed">
    <parent link="wrist2_wrist3/INPUT_INTERFACE"/>
    <child link="HEBI/wrist3/INPUT_INTERFACE"/>
    <origin rpy="1.57079632679 0 0" xyz="0 -.043 .04"/>
  </joint>
  <gazebo reference="wrist2_wrist3/INPUT_INTERFACE">
    <selfCollide>true</selfCollide>
  </gazebo>
  <link name="HEBI/wrist3/INPUT_INTERFACE">
    <visual>
      <origin rpy="0 0 0" xyz="0 0 0"/>
      <geometry>
        <mesh filename="package://hebiros_description/meshes/x5.stl" scale="0.001 0.001 0.001"/>
      </geometry>
      <material name="red">
        <color rgba=".82 0.06 0.06 1"/>
      </material>
    </visual>
    <collision>
      <origin rpy="0 0 0" xyz="0 0 0"/>
      <geometry>
        <mesh filename="package://hebiros_description/meshes/x5.stl" scale="0.001 0.001 0.001"/>
      </geometry>
    </collision>
    <inertial>
      <origin rpy="0 0 0" xyz="-0.0142 -0.0031 0.0165"/>
      <mass value="0.315"/>
      <inertia ixx="0.00015" ixy="0.0000341" ixz="0.0000118" iyy="0.000255" iyz="0.00000229" izz="0.000350"/>
    </inertial>
  </link>
  <joint name="HEBI/wrist3/X5_1" type="continuous">
    <parent link="HEBI/wrist3/INPUT_INTERFACE"/>
    <child link="end_effector/INPUT_INTERFACE"/>
    <origin rpy="0 0 0" xyz="0 0 0.031"/>
    <axis xyz="0 0 1"/>
    <limit effort="2.5" velocity="90"/>
    <dynamics damping="0.1" friction="0.1"/>
  </joint>
  <gazebo reference="HEBI/wrist3/INPUT_INTERFACE">
    <selfCollide>true</selfCollide>
    <gravity>true</gravity>
    <sensor name="HEBI/wrist3/imu_sensor" type="imu">
      <always_on>true</always_on>
      <update_rate>100</update_rate>
      <visualize>true</visualize>
      <plugin filename="libgazebo_ros_imu_sensor.so" name="imu_plugin">
        <topicName>/hebiros_gazebo_plugin/imu/HEBI/wrist3</topicName>
        <bodyName>HEBI/wrist3/imu_link</bodyName>
        <updateRateHZ>10.0</updateRateHZ>
        <gaussianNoise>0.0</gaussianNoise>
        <xyzOffset>0.025 0 0.003</xyzOffset>
        <rpyOffset>0 0 0</rpyOffset>
        <frameName>HEBI/wrist3/imu_link</frameName>
      </plugin>
      <pose>0 0 0 0 0 0</pose>
    </sensor>
  </gazebo>
  <!-- end link -->
  <link name="end_effector/INPUT_INTERFACE">
  </link>
  <gazebo reference="base">
    <selfCollide>true</selfCollide>
  </gazebo>
  <gazebo>
    <plugin filename="libhebiros_gazebo_plugin.so" name="hebiros_gazebo_plugin">
    </plugin>
  </gazebo>
</robot>

