<?xml version="1.0" ?>
<!-- =================================================================================== -->
<!-- |    This document was autogenerated by xacro from igor.xacro                     | -->
<!-- |    EDITING THIS FILE BY HAND IS NOT RECOMMENDED                                 | -->
<!-- =================================================================================== -->
<robot name="igor" xmlns:xacro="http://www.ros.org/wiki/xacro">
  <!-- *************************** XACRO MACROS *************************** -->
  <!-- ************************* ROBOT DEFINITION ************************* -->
  <!-- world link -->
  <!--link name="world" />
  <joint name="world_joint" type="fixed">
    <origin xyz="0 0 0" rpy="0 0 0"/>
    <parent link="world"/>
    <child link="chassis"/>
  </joint-->
  <!-- chassis -->
  <link name="chassis">
    <visual>
      <origin rpy="0 0 0" xyz="0 0 0"/>
      <geometry>
        <box size="0.05 0.3 0.22"/>
      </geometry>
    </visual>
    <collision>
      <origin rpy="0 0 0" xyz="0 0 0"/>
      <geometry>
        <box size="0.05 0.3 0.22"/>
      </geometry>
    </collision>
    <inertial>
      <origin rpy="0 0 0" xyz="0 0 0"/>
      <mass value="1.0"/>
      <inertia ixx="1.0" ixy="0.0" ixz="0.0" iyy="1.0" iyz="0.0" izz="1.0"/>
    </inertial>
  </link>
  <joint name="chassis_leftarm" type="fixed">
    <parent link="chassis"/>
    <child link="leftarm/base/INPUT_INTERFACE"/>
    <origin rpy="0 0 0" xyz="0 0.1 0.11"/>
  </joint>
  <joint name="chassis_rightarm" type="fixed">
    <parent link="chassis"/>
    <child link="rightarm/base/INPUT_INTERFACE"/>
    <origin rpy="0 0 0" xyz="0 -0.1 0.11"/>
  </joint>
  <joint name="chassis_leftleg" type="fixed">
    <parent link="chassis"/>
    <child link="leftleg/base/INPUT_INTERFACE"/>
    <origin rpy="-1.57079632679 0 0" xyz="0 0.15 -0.06"/>
  </joint>
  <joint name="chassis_rightleg" type="fixed">
    <parent link="chassis"/>
    <child link="rightleg/base/INPUT_INTERFACE"/>
    <origin rpy="1.57079632679 0 0" xyz="0 -0.15 -0.06"/>
  </joint>
  <gazebo reference="chassis">
    <selfCollide>true</selfCollide>
    <material>Gazebo/Grey</material>
  </gazebo>
  <!-- component links -->
  <link name="leftarm/base/INPUT_INTERFACE">
    <visual>
      <origin rpy="0 0 0" xyz="0 0 0"/>
      <geometry>
        <mesh filename="package://hebiros_description/meshes/x5.stl" scale="0.001 0.001 0.001"/>
      </geometry>
      <material name="red">
        <color rgba=".82 0.06 0.06 1"/>
      </material>
    </visual>
    <collision>
      <origin rpy="0 0 0" xyz="0 0 0"/>
      <geometry>
        <mesh filename="package://hebiros_description/meshes/x5.stl" scale="0.001 0.001 0.001"/>
      </geometry>
    </collision>
    <inertial>
      <origin rpy="0 0 0" xyz="-0.0142 -0.0031 0.0165"/>
      <mass value="0.335"/>
      <inertia ixx="0.00015" ixy="0.0000341" ixz="0.0000118" iyy="0.000255" iyz="0.00000229" izz="0.000350"/>
    </inertial>
  </link>
  <joint name="leftarm/base/X5_4" type="continuous">
    <parent link="leftarm/base/INPUT_INTERFACE"/>
    <child link="leftarm_base_shoulder/INPUT_INTERFACE"/>
    <origin rpy="0 0 0" xyz="0 0 0.031"/>
    <axis xyz="0 0 1"/>
    <limit effort="7.0" velocity="32"/>
    <dynamics damping="0.1" friction="0.1"/>
  </joint>
  <gazebo reference="leftarm/base/INPUT_INTERFACE">
    <selfCollide>true</selfCollide>
    <gravity>true</gravity>
    <sensor name="leftarm/base/imu_sensor" type="imu">
      <always_on>true</always_on>
      <update_rate>100</update_rate>
      <visualize>true</visualize>
      <plugin filename="libgazebo_ros_imu_sensor.so" name="imu_plugin">
        <topicName>/hebiros_gazebo_plugin/imu/leftarm/base</topicName>
        <bodyName>leftarm/base/imu_link</bodyName>
        <updateRateHZ>10.0</updateRateHZ>
        <gaussianNoise>0.0</gaussianNoise>
        <xyzOffset>0.025 0 0.003</xyzOffset>
        <rpyOffset>0 0 0</rpyOffset>
        <frameName>leftarm/base/imu_link</frameName>
      </plugin>
      <pose>0 0 0 0 0 0</pose>
    </sensor>
    <material>Gazebo/BlueGlow</material>
  </gazebo>
  <link name="leftarm_base_shoulder/INPUT_INTERFACE">
    <visual>
      <origin rpy="1.57079632679 0 1.57079632679" xyz="0 0 0.005"/>
      <geometry>
        <mesh filename="package://hebiros_description/meshes/PM-2149-01.stl" scale="0.001 0.001 0.001"/>
      </geometry>
      <material name="black">
        <color rgba="0 0 0 1"/>
      </material>
    </visual>
    <visual>
      <origin rpy="1.57079632679 0 3.14159265359" xyz="0 -.03 .04"/>
      <geometry>
        <mesh filename="package://hebiros_description/meshes/PM-2150-01L.stl" scale="0.001 0.001 0.001"/>
      </geometry>
      <material name="black">
        <color rgba="0 0 0 1"/>
      </material>
    </visual>
    <collision>
      <origin rpy="1.57079632679 0 1.57079632679" xyz="0 0 0.005"/>
      <geometry>
        <mesh filename="package://hebiros_description/meshes/PM-2149-01.stl" scale="0.001 0.001 0.001"/>
      </geometry>
    </collision>
    <collision>
      <origin rpy="1.57079632679 0 3.14159265359" xyz="0 -.03 .04"/>
      <geometry>
        <mesh filename="package://hebiros_description/meshes/PM-2150-01L.stl" scale="0.001 0.001 0.001"/>
      </geometry>
    </collision>
    <!-- NOTE: inertia is just modelled as small sphere, and could be improved. -->
    <inertial>
      <origin rpy="0 0 0" xyz="0 -0.01125 .0275"/>
      <mass value="0.215"/>
      <inertia ixx="0.0003096" ixy="0.0" ixz="0.0" iyy="0.0003096" iyz="0.0" izz="0.0003096"/>
    </inertial>
  </link>
  <joint name="leftarm_base_shoulder/OUTPUT_INTERFACE" type="fixed">
    <parent link="leftarm_base_shoulder/INPUT_INTERFACE"/>
    <child link="leftarm/shoulder/INPUT_INTERFACE"/>
    <origin rpy="-1.57079632679 0 0" xyz="0 -.0225 .055"/>
  </joint>
  <gazebo reference="leftarm_base_shoulder/INPUT_INTERFACE">
    <selfCollide>true</selfCollide>
  </gazebo>
  <link name="leftarm/shoulder/INPUT_INTERFACE">
    <visual>
      <origin rpy="0 0 0" xyz="0 0 0"/>
      <geometry>
        <mesh filename="package://hebiros_description/meshes/x5.stl" scale="0.001 0.001 0.001"/>
      </geometry>
      <material name="red">
        <color rgba=".82 0.06 0.06 1"/>
      </material>
    </visual>
    <collision>
      <origin rpy="0 0 0" xyz="0 0 0"/>
      <geometry>
        <mesh filename="package://hebiros_description/meshes/x5.stl" scale="0.001 0.001 0.001"/>
      </geometry>
    </collision>
    <inertial>
      <origin rpy="0 0 0" xyz="-0.0142 -0.0031 0.0165"/>
      <mass value="0.335"/>
      <inertia ixx="0.00015" ixy="0.0000341" ixz="0.0000118" iyy="0.000255" iyz="0.00000229" izz="0.000350"/>
    </inertial>
  </link>
  <joint name="leftarm/shoulder/X5_4" type="continuous">
    <parent link="leftarm/shoulder/INPUT_INTERFACE"/>
    <child link="leftarm_shoulder_elbow/INPUT_INTERFACE"/>
    <origin rpy="0 0 0" xyz="0 0 0.031"/>
    <axis xyz="0 0 1"/>
    <limit effort="7.0" velocity="32"/>
    <dynamics damping="0.1" friction="0.1"/>
  </joint>
  <gazebo reference="leftarm/shoulder/INPUT_INTERFACE">
    <selfCollide>true</selfCollide>
    <gravity>true</gravity>
    <sensor name="leftarm/shoulder/imu_sensor" type="imu">
      <always_on>true</always_on>
      <update_rate>100</update_rate>
      <visualize>true</visualize>
      <plugin filename="libgazebo_ros_imu_sensor.so" name="imu_plugin">
        <topicName>/hebiros_gazebo_plugin/imu/leftarm/shoulder</topicName>
        <bodyName>leftarm/shoulder/imu_link</bodyName>
        <updateRateHZ>10.0</updateRateHZ>
        <gaussianNoise>0.0</gaussianNoise>
        <xyzOffset>0.025 0 0.003</xyzOffset>
        <rpyOffset>0 0 0</rpyOffset>
        <frameName>leftarm/shoulder/imu_link</frameName>
      </plugin>
      <pose>0 0 0 0 0 0</pose>
    </sensor>
    <material>Gazebo/BlueGlow</material>
  </gazebo>
  <link name="leftarm_shoulder_elbow/INPUT_INTERFACE">
    <visual>
      <origin rpy="0 0 0" xyz="0 0 0"/>
      <geometry>
        <mesh filename="package://hebiros_description/meshes/A-2038-02.stl"/>
      </geometry>
      <material name="black">
        <color rgba="0 0 0 1"/>
      </material>
    </visual>
    <visual>
      <origin rpy="0 1.57075 0" xyz="0.165 0 0.02"/>
      <geometry>
        <cylinder length="0.3046" radius=".016"/>
      </geometry>
      <material name="silver">
        <color rgba="0.6 0.6 0.6 1"/>
      </material>
    </visual>
    <visual>
      <origin rpy="0 0 0" xyz="0.33 0.0 0.04"/>
      <geometry>
        <mesh filename="package://hebiros_description/meshes/A-2039-02.stl"/>
      </geometry>
      <material name="black">
        <color rgba="0 0 0 1"/>
      </material>
    </visual>
    <collision>
      <origin rpy="0 0 0" xyz="0 0 0"/>
      <geometry>
        <mesh filename="package://hebiros_description/meshes/A-2038-02.stl"/>
      </geometry>
    </collision>
    <collision>
      <origin rpy="0 1.57075 0" xyz="0.165 0 0.02"/>
      <geometry>
        <cylinder length="0.3046" radius=".016"/>
      </geometry>
    </collision>
    <collision>
      <origin rpy="0 0 0" xyz="0.33 0.0 0.04"/>
      <geometry>
        <mesh filename="package://hebiros_description/meshes/A-2039-02.stl"/>
      </geometry>
    </collision>
    <!-- Approximate inertia as thin rod about x axis -->
    <inertial>
      <origin rpy="0 0 0" xyz="0.165 0 0.02"/>
      <mass value="0.404"/>
      <inertia ixx="0.0" ixy="0.0" ixz="0.0" iyy="0.0036663" iyz="0.0" izz="0.0036663"/>
    </inertial>
  </link>
  <joint name="leftarm_shoulder_elbow/OUTPUT_JOINT" type="fixed">
    <parent link="leftarm_shoulder_elbow/INPUT_INTERFACE"/>
    <child link="leftarm/elbow/INPUT_INTERFACE"/>
    <origin rpy="0 0 0" xyz="0.33 -0.0 0.04"/>
  </joint>
  <gazebo reference="leftarm_shoulder_elbow/INPUT_INTERFACE">
    <selfCollide>true</selfCollide>
    <material>Gazebo/FlatBlack</material>
  </gazebo>
  <link name="leftarm/elbow/INPUT_INTERFACE">
    <visual>
      <origin rpy="0 0 0" xyz="0 0 0"/>
      <geometry>
        <mesh filename="package://hebiros_description/meshes/x5.stl" scale="0.001 0.001 0.001"/>
      </geometry>
      <material name="red">
        <color rgba=".82 0.06 0.06 1"/>
      </material>
    </visual>
    <collision>
      <origin rpy="0 0 0" xyz="0 0 0"/>
      <geometry>
        <mesh filename="package://hebiros_description/meshes/x5.stl" scale="0.001 0.001 0.001"/>
      </geometry>
    </collision>
    <inertial>
      <origin rpy="0 0 0" xyz="-0.0142 -0.0031 0.0165"/>
      <mass value="0.335"/>
      <inertia ixx="0.00015" ixy="0.0000341" ixz="0.0000118" iyy="0.000255" iyz="0.00000229" izz="0.000350"/>
    </inertial>
  </link>
  <joint name="leftarm/elbow/X5_4" type="continuous">
    <parent link="leftarm/elbow/INPUT_INTERFACE"/>
    <child link="leftarm_elbow_hand/INPUT_INTERFACE"/>
    <origin rpy="0 0 0" xyz="0 0 0.031"/>
    <axis xyz="0 0 1"/>
    <limit effort="7.0" velocity="32"/>
    <dynamics damping="0.1" friction="0.1"/>
  </joint>
  <gazebo reference="leftarm/elbow/INPUT_INTERFACE">
    <selfCollide>true</selfCollide>
    <gravity>true</gravity>
    <sensor name="leftarm/elbow/imu_sensor" type="imu">
      <always_on>true</always_on>
      <update_rate>100</update_rate>
      <visualize>true</visualize>
      <plugin filename="libgazebo_ros_imu_sensor.so" name="imu_plugin">
        <topicName>/hebiros_gazebo_plugin/imu/leftarm/elbow</topicName>
        <bodyName>leftarm/elbow/imu_link</bodyName>
        <updateRateHZ>10.0</updateRateHZ>
        <gaussianNoise>0.0</gaussianNoise>
        <xyzOffset>0.025 0 0.003</xyzOffset>
        <rpyOffset>0 0 0</rpyOffset>
        <frameName>leftarm/elbow/imu_link</frameName>
      </plugin>
      <pose>0 0 0 0 0 0</pose>
    </sensor>
    <material>Gazebo/BlueGlow</material>
  </gazebo>
  <link name="leftarm_elbow_hand/INPUT_INTERFACE">
    <visual>
      <origin rpy="0 0 0" xyz="0 0 0"/>
      <geometry>
        <mesh filename="package://hebiros_description/meshes/A-2038-02.stl"/>
      </geometry>
      <material name="black">
        <color rgba="0 0 0 1"/>
      </material>
    </visual>
    <visual>
      <origin rpy="0 1.57075 0" xyz="0.165 0 0.02"/>
      <geometry>
        <cylinder length="0.3046" radius=".016"/>
      </geometry>
      <material name="silver">
        <color rgba="0.6 0.6 0.6 1"/>
      </material>
    </visual>
    <visual>
      <origin rpy="-3.14159265359 0 0" xyz="0.33 -2.44929359829e-18 0.0"/>
      <geometry>
        <mesh filename="package://hebiros_description/meshes/A-2039-02.stl"/>
      </geometry>
      <material name="black">
        <color rgba="0 0 0 1"/>
      </material>
    </visual>
    <collision>
      <origin rpy="0 0 0" xyz="0 0 0"/>
      <geometry>
        <mesh filename="package://hebiros_description/meshes/A-2038-02.stl"/>
      </geometry>
    </collision>
    <collision>
      <origin rpy="0 1.57075 0" xyz="0.165 0 0.02"/>
      <geometry>
        <cylinder length="0.3046" radius=".016"/>
      </geometry>
    </collision>
    <collision>
      <origin rpy="-3.14159265359 0 0" xyz="0.33 -2.44929359829e-18 0.0"/>
      <geometry>
        <mesh filename="package://hebiros_description/meshes/A-2039-02.stl"/>
      </geometry>
    </collision>
    <!-- Approximate inertia as thin rod about x axis -->
    <inertial>
      <origin rpy="0 0 0" xyz="0.165 0 0.02"/>
      <mass value="0.404"/>
      <inertia ixx="0.0" ixy="0.0" ixz="0.0" iyy="0.0036663" iyz="0.0" izz="0.0036663"/>
    </inertial>
  </link>
  <joint name="leftarm_elbow_hand/OUTPUT_JOINT" type="fixed">
    <parent link="leftarm_elbow_hand/INPUT_INTERFACE"/>
    <child link="leftarm/hand/INPUT_INTERFACE"/>
    <origin rpy="3.14159265359 0 0" xyz="0.33 -2.44929359829e-18 0.0"/>
  </joint>
  <gazebo reference="leftarm_elbow_hand/INPUT_INTERFACE">
    <selfCollide>true</selfCollide>
    <material>Gazebo/FlatBlack</material>
  </gazebo>
  <link name="leftarm/hand/INPUT_INTERFACE">
    <visual>
      <origin rpy="0 0 0" xyz="0 0 0"/>
      <geometry>
        <mesh filename="package://hebiros_description/meshes/x5.stl" scale="0.001 0.001 0.001"/>
      </geometry>
      <material name="red">
        <color rgba=".82 0.06 0.06 1"/>
      </material>
    </visual>
    <collision>
      <origin rpy="0 0 0" xyz="0 0 0"/>
      <geometry>
        <mesh filename="package://hebiros_description/meshes/x5.stl" scale="0.001 0.001 0.001"/>
      </geometry>
    </collision>
    <inertial>
      <origin rpy="0 0 0" xyz="-0.0142 -0.0031 0.0165"/>
      <mass value="0.335"/>
      <inertia ixx="0.00015" ixy="0.0000341" ixz="0.0000118" iyy="0.000255" iyz="0.00000229" izz="0.000350"/>
    </inertial>
  </link>
  <joint name="leftarm/hand/X5_4" type="continuous">
    <parent link="leftarm/hand/INPUT_INTERFACE"/>
    <child link="leftarm_end_effector/INPUT_INTERFACE"/>
    <origin rpy="0 0 0" xyz="0 0 0.031"/>
    <axis xyz="0 0 1"/>
    <limit effort="7.0" velocity="32"/>
    <dynamics damping="0.1" friction="0.1"/>
  </joint>
  <gazebo reference="leftarm/hand/INPUT_INTERFACE">
    <selfCollide>true</selfCollide>
    <gravity>true</gravity>
    <sensor name="leftarm/hand/imu_sensor" type="imu">
      <always_on>true</always_on>
      <update_rate>100</update_rate>
      <visualize>true</visualize>
      <plugin filename="libgazebo_ros_imu_sensor.so" name="imu_plugin">
        <topicName>/hebiros_gazebo_plugin/imu/leftarm/hand</topicName>
        <bodyName>leftarm/hand/imu_link</bodyName>
        <updateRateHZ>10.0</updateRateHZ>
        <gaussianNoise>0.0</gaussianNoise>
        <xyzOffset>0.025 0 0.003</xyzOffset>
        <rpyOffset>0 0 0</rpyOffset>
        <frameName>leftarm/hand/imu_link</frameName>
      </plugin>
      <pose>0 0 0 0 0 0</pose>
    </sensor>
    <material>Gazebo/BlueGlow</material>
  </gazebo>
  <link name="rightarm/base/INPUT_INTERFACE">
    <visual>
      <origin rpy="0 0 0" xyz="0 0 0"/>
      <geometry>
        <mesh filename="package://hebiros_description/meshes/x5.stl" scale="0.001 0.001 0.001"/>
      </geometry>
      <material name="red">
        <color rgba=".82 0.06 0.06 1"/>
      </material>
    </visual>
    <collision>
      <origin rpy="0 0 0" xyz="0 0 0"/>
      <geometry>
        <mesh filename="package://hebiros_description/meshes/x5.stl" scale="0.001 0.001 0.001"/>
      </geometry>
    </collision>
    <inertial>
      <origin rpy="0 0 0" xyz="-0.0142 -0.0031 0.0165"/>
      <mass value="0.335"/>
      <inertia ixx="0.00015" ixy="0.0000341" ixz="0.0000118" iyy="0.000255" iyz="0.00000229" izz="0.000350"/>
    </inertial>
  </link>
  <joint name="rightarm/base/X5_4" type="continuous">
    <parent link="rightarm/base/INPUT_INTERFACE"/>
    <child link="rightarm_base_shoulder/INPUT_INTERFACE"/>
    <origin rpy="0 0 0" xyz="0 0 0.031"/>
    <axis xyz="0 0 1"/>
    <limit effort="7.0" velocity="32"/>
    <dynamics damping="0.1" friction="0.1"/>
  </joint>
  <gazebo reference="rightarm/base/INPUT_INTERFACE">
    <selfCollide>true</selfCollide>
    <gravity>true</gravity>
    <sensor name="rightarm/base/imu_sensor" type="imu">
      <always_on>true</always_on>
      <update_rate>100</update_rate>
      <visualize>true</visualize>
      <plugin filename="libgazebo_ros_imu_sensor.so" name="imu_plugin">
        <topicName>/hebiros_gazebo_plugin/imu/rightarm/base</topicName>
        <bodyName>rightarm/base/imu_link</bodyName>
        <updateRateHZ>10.0</updateRateHZ>
        <gaussianNoise>0.0</gaussianNoise>
        <xyzOffset>0.025 0 0.003</xyzOffset>
        <rpyOffset>0 0 0</rpyOffset>
        <frameName>rightarm/base/imu_link</frameName>
      </plugin>
      <pose>0 0 0 0 0 0</pose>
    </sensor>
    <material>Gazebo/BlueGlow</material>
  </gazebo>
  <link name="rightarm_base_shoulder/INPUT_INTERFACE">
    <visual>
      <origin rpy="1.57079632679 0 -1.57079632679" xyz="0 0 0.005"/>
      <geometry>
        <mesh filename="package://hebiros_description/meshes/PM-2149-01.stl" scale="0.001 0.001 0.001"/>
      </geometry>
      <material name="black">
        <color rgba="0 0 0 1"/>
      </material>
    </visual>
    <visual>
      <origin rpy="1.57079632679 0 0" xyz="0 .03 .04"/>
      <geometry>
        <mesh filename="package://hebiros_description/meshes/PM-2150-01R.stl" scale="0.001 0.001 0.001"/>
      </geometry>
      <material name="black">
        <color rgba="0 0 0 1"/>
      </material>
    </visual>
    <collision>
      <origin rpy="1.57079632679 0 -1.57079632679" xyz="0 0 0.005"/>
      <geometry>
        <mesh filename="package://hebiros_description/meshes/PM-2149-01.stl" scale="0.001 0.001 0.001"/>
      </geometry>
    </collision>
    <collision>
      <origin rpy="1.57079632679 0 0" xyz="0 .03 .04"/>
      <geometry>
        <mesh filename="package://hebiros_description/meshes/PM-2150-01R.stl" scale="0.001 0.001 0.001"/>
      </geometry>
    </collision>
    <!-- NOTE: inertia is just modelled as small sphere, and could be improved. -->
    <inertial>
      <origin rpy="0 0 0" xyz="0 0.01125 .0275"/>
      <mass value="0.215"/>
      <inertia ixx="0.0003096" ixy="0.0" ixz="0.0" iyy="0.0003096" iyz="0.0" izz="0.0003096"/>
    </inertial>
  </link>
  <joint name="rightarm_base_shoulder/OUTPUT_INTERFACE" type="fixed">
    <parent link="rightarm_base_shoulder/INPUT_INTERFACE"/>
    <child link="rightarm/shoulder/INPUT_INTERFACE"/>
    <origin rpy="1.57079632679 0 0" xyz="0 .0225 .055"/>
  </joint>
  <gazebo reference="rightarm_base_shoulder/INPUT_INTERFACE">
    <selfCollide>true</selfCollide>
  </gazebo>
  <link name="rightarm/shoulder/INPUT_INTERFACE">
    <visual>
      <origin rpy="0 0 0" xyz="0 0 0"/>
      <geometry>
        <mesh filename="package://hebiros_description/meshes/x5.stl" scale="0.001 0.001 0.001"/>
      </geometry>
      <material name="red">
        <color rgba=".82 0.06 0.06 1"/>
      </material>
    </visual>
    <collision>
      <origin rpy="0 0 0" xyz="0 0 0"/>
      <geometry>
        <mesh filename="package://hebiros_description/meshes/x5.stl" scale="0.001 0.001 0.001"/>
      </geometry>
    </collision>
    <inertial>
      <origin rpy="0 0 0" xyz="-0.0142 -0.0031 0.0165"/>
      <mass value="0.335"/>
      <inertia ixx="0.00015" ixy="0.0000341" ixz="0.0000118" iyy="0.000255" iyz="0.00000229" izz="0.000350"/>
    </inertial>
  </link>
  <joint name="rightarm/shoulder/X5_4" type="continuous">
    <parent link="rightarm/shoulder/INPUT_INTERFACE"/>
    <child link="rightarm_shoulder_elbow/INPUT_INTERFACE"/>
    <origin rpy="0 0 0" xyz="0 0 0.031"/>
    <axis xyz="0 0 1"/>
    <limit effort="7.0" velocity="32"/>
    <dynamics damping="0.1" friction="0.1"/>
  </joint>
  <gazebo reference="rightarm/shoulder/INPUT_INTERFACE">
    <selfCollide>true</selfCollide>
    <gravity>true</gravity>
    <sensor name="rightarm/shoulder/imu_sensor" type="imu">
      <always_on>true</always_on>
      <update_rate>100</update_rate>
      <visualize>true</visualize>
      <plugin filename="libgazebo_ros_imu_sensor.so" name="imu_plugin">
        <topicName>/hebiros_gazebo_plugin/imu/rightarm/shoulder</topicName>
        <bodyName>rightarm/shoulder/imu_link</bodyName>
        <updateRateHZ>10.0</updateRateHZ>
        <gaussianNoise>0.0</gaussianNoise>
        <xyzOffset>0.025 0 0.003</xyzOffset>
        <rpyOffset>0 0 0</rpyOffset>
        <frameName>rightarm/shoulder/imu_link</frameName>
      </plugin>
      <pose>0 0 0 0 0 0</pose>
    </sensor>
    <material>Gazebo/BlueGlow</material>
  </gazebo>
  <link name="rightarm_shoulder_elbow/INPUT_INTERFACE">
    <visual>
      <origin rpy="0 0 0" xyz="0 0 0"/>
      <geometry>
        <mesh filename="package://hebiros_description/meshes/A-2038-02.stl"/>
      </geometry>
      <material name="black">
        <color rgba="0 0 0 1"/>
      </material>
    </visual>
    <visual>
      <origin rpy="0 1.57075 0" xyz="0.165 0 0.02"/>
      <geometry>
        <cylinder length="0.3046" radius=".016"/>
      </geometry>
      <material name="silver">
        <color rgba="0.6 0.6 0.6 1"/>
      </material>
    </visual>
    <visual>
      <origin rpy="0 0 0" xyz="0.33 0.0 0.04"/>
      <geometry>
        <mesh filename="package://hebiros_description/meshes/A-2039-02.stl"/>
      </geometry>
      <material name="black">
        <color rgba="0 0 0 1"/>
      </material>
    </visual>
    <collision>
      <origin rpy="0 0 0" xyz="0 0 0"/>
      <geometry>
        <mesh filename="package://hebiros_description/meshes/A-2038-02.stl"/>
      </geometry>
    </collision>
    <collision>
      <origin rpy="0 1.57075 0" xyz="0.165 0 0.02"/>
      <geometry>
        <cylinder length="0.3046" radius=".016"/>
      </geometry>
    </collision>
    <collision>
      <origin rpy="0 0 0" xyz="0.33 0.0 0.04"/>
      <geometry>
        <mesh filename="package://hebiros_description/meshes/A-2039-02.stl"/>
      </geometry>
    </collision>
    <!-- Approximate inertia as thin rod about x axis -->
    <inertial>
      <origin rpy="0 0 0" xyz="0.165 0 0.02"/>
      <mass value="0.404"/>
      <inertia ixx="0.0" ixy="0.0" ixz="0.0" iyy="0.0036663" iyz="0.0" izz="0.0036663"/>
    </inertial>
  </link>
  <joint name="rightarm_shoulder_elbow/OUTPUT_JOINT" type="fixed">
    <parent link="rightarm_shoulder_elbow/INPUT_INTERFACE"/>
    <child link="rightarm/elbow/INPUT_INTERFACE"/>
    <origin rpy="0 0 0" xyz="0.33 -0.0 0.04"/>
  </joint>
  <gazebo reference="rightarm_shoulder_elbow/INPUT_INTERFACE">
    <selfCollide>true</selfCollide>
    <material>Gazebo/FlatBlack</material>
  </gazebo>
  <link name="rightarm/elbow/INPUT_INTERFACE">
    <visual>
      <origin rpy="0 0 0" xyz="0 0 0"/>
      <geometry>
        <mesh filename="package://hebiros_description/meshes/x5.stl" scale="0.001 0.001 0.001"/>
      </geometry>
      <material name="red">
        <color rgba=".82 0.06 0.06 1"/>
      </material>
    </visual>
    <collision>
      <origin rpy="0 0 0" xyz="0 0 0"/>
      <geometry>
        <mesh filename="package://hebiros_description/meshes/x5.stl" scale="0.001 0.001 0.001"/>
      </geometry>
    </collision>
    <inertial>
      <origin rpy="0 0 0" xyz="-0.0142 -0.0031 0.0165"/>
      <mass value="0.335"/>
      <inertia ixx="0.00015" ixy="0.0000341" ixz="0.0000118" iyy="0.000255" iyz="0.00000229" izz="0.000350"/>
    </inertial>
  </link>
  <joint name="rightarm/elbow/X5_4" type="continuous">
    <parent link="rightarm/elbow/INPUT_INTERFACE"/>
    <child link="rightarm_elbow_hand/INPUT_INTERFACE"/>
    <origin rpy="0 0 0" xyz="0 0 0.031"/>
    <axis xyz="0 0 1"/>
    <limit effort="7.0" velocity="32"/>
    <dynamics damping="0.1" friction="0.1"/>
  </joint>
  <gazebo reference="rightarm/elbow/INPUT_INTERFACE">
    <selfCollide>true</selfCollide>
    <gravity>true</gravity>
    <sensor name="rightarm/elbow/imu_sensor" type="imu">
      <always_on>true</always_on>
      <update_rate>100</update_rate>
      <visualize>true</visualize>
      <plugin filename="libgazebo_ros_imu_sensor.so" name="imu_plugin">
        <topicName>/hebiros_gazebo_plugin/imu/rightarm/elbow</topicName>
        <bodyName>rightarm/elbow/imu_link</bodyName>
        <updateRateHZ>10.0</updateRateHZ>
        <gaussianNoise>0.0</gaussianNoise>
        <xyzOffset>0.025 0 0.003</xyzOffset>
        <rpyOffset>0 0 0</rpyOffset>
        <frameName>rightarm/elbow/imu_link</frameName>
      </plugin>
      <pose>0 0 0 0 0 0</pose>
    </sensor>
    <material>Gazebo/BlueGlow</material>
  </gazebo>
  <link name="rightarm_elbow_hand/INPUT_INTERFACE">
    <visual>
      <origin rpy="0 0 0" xyz="0 0 0"/>
      <geometry>
        <mesh filename="package://hebiros_description/meshes/A-2038-02.stl"/>
      </geometry>
      <material name="black">
        <color rgba="0 0 0 1"/>
      </material>
    </visual>
    <visual>
      <origin rpy="0 1.57075 0" xyz="0.165 0 0.02"/>
      <geometry>
        <cylinder length="0.3046" radius=".016"/>
      </geometry>
      <material name="silver">
        <color rgba="0.6 0.6 0.6 1"/>
      </material>
    </visual>
    <visual>
      <origin rpy="-3.14159265359 0 0" xyz="0.33 -2.44929359829e-18 0.0"/>
      <geometry>
        <mesh filename="package://hebiros_description/meshes/A-2039-02.stl"/>
      </geometry>
      <material name="black">
        <color rgba="0 0 0 1"/>
      </material>
    </visual>
    <collision>
      <origin rpy="0 0 0" xyz="0 0 0"/>
      <geometry>
        <mesh filename="package://hebiros_description/meshes/A-2038-02.stl"/>
      </geometry>
    </collision>
    <collision>
      <origin rpy="0 1.57075 0" xyz="0.165 0 0.02"/>
      <geometry>
        <cylinder length="0.3046" radius=".016"/>
      </geometry>
    </collision>
    <collision>
      <origin rpy="-3.14159265359 0 0" xyz="0.33 -2.44929359829e-18 0.0"/>
      <geometry>
        <mesh filename="package://hebiros_description/meshes/A-2039-02.stl"/>
      </geometry>
    </collision>
    <!-- Approximate inertia as thin rod about x axis -->
    <inertial>
      <origin rpy="0 0 0" xyz="0.165 0 0.02"/>
      <mass value="0.404"/>
      <inertia ixx="0.0" ixy="0.0" ixz="0.0" iyy="0.0036663" iyz="0.0" izz="0.0036663"/>
    </inertial>
  </link>
  <joint name="rightarm_elbow_hand/OUTPUT_JOINT" type="fixed">
    <parent link="rightarm_elbow_hand/INPUT_INTERFACE"/>
    <child link="rightarm/hand/INPUT_INTERFACE"/>
    <origin rpy="3.14159265359 0 0" xyz="0.33 -2.44929359829e-18 0.0"/>
  </joint>
  <gazebo reference="rightarm_elbow_hand/INPUT_INTERFACE">
    <selfCollide>true</selfCollide>
    <material>Gazebo/FlatBlack</material>
  </gazebo>
  <link name="rightarm/hand/INPUT_INTERFACE">
    <visual>
      <origin rpy="0 0 0" xyz="0 0 0"/>
      <geometry>
        <mesh filename="package://hebiros_description/meshes/x5.stl" scale="0.001 0.001 0.001"/>
      </geometry>
      <material name="red">
        <color rgba=".82 0.06 0.06 1"/>
      </material>
    </visual>
    <collision>
      <origin rpy="0 0 0" xyz="0 0 0"/>
      <geometry>
        <mesh filename="package://hebiros_description/meshes/x5.stl" scale="0.001 0.001 0.001"/>
      </geometry>
    </collision>
    <inertial>
      <origin rpy="0 0 0" xyz="-0.0142 -0.0031 0.0165"/>
      <mass value="0.335"/>
      <inertia ixx="0.00015" ixy="0.0000341" ixz="0.0000118" iyy="0.000255" iyz="0.00000229" izz="0.000350"/>
    </inertial>
  </link>
  <joint name="rightarm/hand/X5_4" type="continuous">
    <parent link="rightarm/hand/INPUT_INTERFACE"/>
    <child link="rightarm_end_effector/INPUT_INTERFACE"/>
    <origin rpy="0 0 0" xyz="0 0 0.031"/>
    <axis xyz="0 0 1"/>
    <limit effort="7.0" velocity="32"/>
    <dynamics damping="0.1" friction="0.1"/>
  </joint>
  <gazebo reference="rightarm/hand/INPUT_INTERFACE">
    <selfCollide>true</selfCollide>
    <gravity>true</gravity>
    <sensor name="rightarm/hand/imu_sensor" type="imu">
      <always_on>true</always_on>
      <update_rate>100</update_rate>
      <visualize>true</visualize>
      <plugin filename="libgazebo_ros_imu_sensor.so" name="imu_plugin">
        <topicName>/hebiros_gazebo_plugin/imu/rightarm/hand</topicName>
        <bodyName>rightarm/hand/imu_link</bodyName>
        <updateRateHZ>10.0</updateRateHZ>
        <gaussianNoise>0.0</gaussianNoise>
        <xyzOffset>0.025 0 0.003</xyzOffset>
        <rpyOffset>0 0 0</rpyOffset>
        <frameName>rightarm/hand/imu_link</frameName>
      </plugin>
      <pose>0 0 0 0 0 0</pose>
    </sensor>
    <material>Gazebo/BlueGlow</material>
  </gazebo>
  <link name="leftleg/base/INPUT_INTERFACE">
    <visual>
      <origin rpy="0 0 0" xyz="0 0 0"/>
      <geometry>
        <mesh filename="package://hebiros_description/meshes/x5.stl" scale="0.001 0.001 0.001"/>
      </geometry>
      <material name="red">
        <color rgba=".82 0.06 0.06 1"/>
      </material>
    </visual>
    <collision>
      <origin rpy="0 0 0" xyz="0 0 0"/>
      <geometry>
        <mesh filename="package://hebiros_description/meshes/x5.stl" scale="0.001 0.001 0.001"/>
      </geometry>
    </collision>
    <inertial>
      <origin rpy="0 0 0" xyz="-0.0142 -0.0031 0.0165"/>
      <mass value="0.335"/>
      <inertia ixx="0.00015" ixy="0.0000341" ixz="0.0000118" iyy="0.000255" iyz="0.00000229" izz="0.000350"/>
    </inertial>
  </link>
  <joint name="leftleg/base/X5_4" type="continuous">
    <parent link="leftleg/base/INPUT_INTERFACE"/>
    <child link="leftleg_base_knee/INPUT_INTERFACE"/>
    <origin rpy="0 0 0" xyz="0 0 0.031"/>
    <axis xyz="0 0 1"/>
    <limit effort="7.0" velocity="32"/>
    <dynamics damping="0.1" friction="0.1"/>
  </joint>
  <gazebo reference="leftleg/base/INPUT_INTERFACE">
    <selfCollide>true</selfCollide>
    <gravity>true</gravity>
    <sensor name="leftleg/base/imu_sensor" type="imu">
      <always_on>true</always_on>
      <update_rate>100</update_rate>
      <visualize>true</visualize>
      <plugin filename="libgazebo_ros_imu_sensor.so" name="imu_plugin">
        <topicName>/hebiros_gazebo_plugin/imu/leftleg/base</topicName>
        <bodyName>leftleg/base/imu_link</bodyName>
        <updateRateHZ>10.0</updateRateHZ>
        <gaussianNoise>0.0</gaussianNoise>
        <xyzOffset>0.025 0 0.003</xyzOffset>
        <rpyOffset>0 0 0</rpyOffset>
        <frameName>leftleg/base/imu_link</frameName>
      </plugin>
      <pose>0 0 0 0 0 0</pose>
    </sensor>
    <material>Gazebo/BlueGlow</material>
  </gazebo>
  <link name="leftleg_base_knee/INPUT_INTERFACE">
    <visual>
      <origin rpy="0 0 0" xyz="0 0 0"/>
      <geometry>
        <mesh filename="package://hebiros_description/meshes/A-2038-02.stl"/>
      </geometry>
      <material name="black">
        <color rgba="0 0 0 1"/>
      </material>
    </visual>
    <visual>
      <origin rpy="0 1.57075 0" xyz="0.19 0 0.02"/>
      <geometry>
        <cylinder length="0.3546" radius=".016"/>
      </geometry>
      <material name="silver">
        <color rgba="0.6 0.6 0.6 1"/>
      </material>
    </visual>
    <visual>
      <origin rpy="-3.14159265359 0 0" xyz="0.38 -2.44929359829e-18 0.0"/>
      <geometry>
        <mesh filename="package://hebiros_description/meshes/A-2039-02.stl"/>
      </geometry>
      <material name="black">
        <color rgba="0 0 0 1"/>
      </material>
    </visual>
    <collision>
      <origin rpy="0 0 0" xyz="0 0 0"/>
      <geometry>
        <mesh filename="package://hebiros_description/meshes/A-2038-02.stl"/>
      </geometry>
    </collision>
    <collision>
      <origin rpy="0 1.57075 0" xyz="0.19 0 0.02"/>
      <geometry>
        <cylinder length="0.3546" radius=".016"/>
      </geometry>
    </collision>
    <collision>
      <origin rpy="-3.14159265359 0 0" xyz="0.38 -2.44929359829e-18 0.0"/>
      <geometry>
        <mesh filename="package://hebiros_description/meshes/A-2039-02.stl"/>
      </geometry>
    </collision>
    <!-- Approximate inertia as thin rod about x axis -->
    <inertial>
      <origin rpy="0 0 0" xyz="0.19 0 0.02"/>
      <mass value="0.424"/>
      <inertia ixx="0.0" ixy="0.0" ixz="0.0" iyy="0.00510213333333" iyz="0.0" izz="0.00510213333333"/>
    </inertial>
  </link>
  <joint name="leftleg_base_knee/OUTPUT_JOINT" type="fixed">
    <parent link="leftleg_base_knee/INPUT_INTERFACE"/>
    <child link="leftleg/knee/INPUT_INTERFACE"/>
    <origin rpy="3.14159265359 0 0" xyz="0.38 -2.44929359829e-18 0.0"/>
  </joint>
  <gazebo reference="leftleg_base_knee/INPUT_INTERFACE">
    <selfCollide>true</selfCollide>
    <material>Gazebo/FlatBlack</material>
  </gazebo>
  <link name="leftleg/knee/INPUT_INTERFACE">
    <visual>
      <origin rpy="0 0 0" xyz="0 0 0"/>
      <geometry>
        <mesh filename="package://hebiros_description/meshes/x5.stl" scale="0.001 0.001 0.001"/>
      </geometry>
      <material name="red">
        <color rgba=".82 0.06 0.06 1"/>
      </material>
    </visual>
    <collision>
      <origin rpy="0 0 0" xyz="0 0 0"/>
      <geometry>
        <mesh filename="package://hebiros_description/meshes/x5.stl" scale="0.001 0.001 0.001"/>
      </geometry>
    </collision>
    <inertial>
      <origin rpy="0 0 0" xyz="-0.0142 -0.0031 0.0165"/>
      <mass value="0.335"/>
      <inertia ixx="0.00015" ixy="0.0000341" ixz="0.0000118" iyy="0.000255" iyz="0.00000229" izz="0.000350"/>
    </inertial>
  </link>
  <joint name="leftleg/knee/X5_4" type="continuous">
    <parent link="leftleg/knee/INPUT_INTERFACE"/>
    <child link="leftleg_knee_foot/INPUT_INTERFACE"/>
    <origin rpy="0 0 0" xyz="0 0 0.031"/>
    <axis xyz="0 0 1"/>
    <limit effort="7.0" velocity="32"/>
    <dynamics damping="0.1" friction="0.1"/>
  </joint>
  <gazebo reference="leftleg/knee/INPUT_INTERFACE">
    <selfCollide>true</selfCollide>
    <gravity>true</gravity>
    <sensor name="leftleg/knee/imu_sensor" type="imu">
      <always_on>true</always_on>
      <update_rate>100</update_rate>
      <visualize>true</visualize>
      <plugin filename="libgazebo_ros_imu_sensor.so" name="imu_plugin">
        <topicName>/hebiros_gazebo_plugin/imu/leftleg/knee</topicName>
        <bodyName>leftleg/knee/imu_link</bodyName>
        <updateRateHZ>10.0</updateRateHZ>
        <gaussianNoise>0.0</gaussianNoise>
        <xyzOffset>0.025 0 0.003</xyzOffset>
        <rpyOffset>0 0 0</rpyOffset>
        <frameName>leftleg/knee/imu_link</frameName>
      </plugin>
      <pose>0 0 0 0 0 0</pose>
    </sensor>
    <material>Gazebo/BlueGlow</material>
  </gazebo>
  <link name="leftleg_knee_foot/INPUT_INTERFACE">
    <visual>
      <origin rpy="0 0 0" xyz="0 0 0"/>
      <geometry>
        <mesh filename="package://hebiros_description/meshes/A-2038-02.stl"/>
      </geometry>
      <material name="black">
        <color rgba="0 0 0 1"/>
      </material>
    </visual>
    <visual>
      <origin rpy="0 1.57075 0" xyz="0.19 0 0.02"/>
      <geometry>
        <cylinder length="0.3546" radius=".016"/>
      </geometry>
      <material name="silver">
        <color rgba="0.6 0.6 0.6 1"/>
      </material>
    </visual>
    <visual>
      <origin rpy="-3.14159265359 0 0" xyz="0.38 -2.44929359829e-18 0.0"/>
      <geometry>
        <mesh filename="package://hebiros_description/meshes/A-2039-02.stl"/>
      </geometry>
      <material name="black">
        <color rgba="0 0 0 1"/>
      </material>
    </visual>
    <collision>
      <origin rpy="0 0 0" xyz="0 0 0"/>
      <geometry>
        <mesh filename="package://hebiros_description/meshes/A-2038-02.stl"/>
      </geometry>
    </collision>
    <collision>
      <origin rpy="0 1.57075 0" xyz="0.19 0 0.02"/>
      <geometry>
        <cylinder length="0.3546" radius=".016"/>
      </geometry>
    </collision>
    <collision>
      <origin rpy="-3.14159265359 0 0" xyz="0.38 -2.44929359829e-18 0.0"/>
      <geometry>
        <mesh filename="package://hebiros_description/meshes/A-2039-02.stl"/>
      </geometry>
    </collision>
    <!-- Approximate inertia as thin rod about x axis -->
    <inertial>
      <origin rpy="0 0 0" xyz="0.19 0 0.02"/>
      <mass value="0.424"/>
      <inertia ixx="0.0" ixy="0.0" ixz="0.0" iyy="0.00510213333333" iyz="0.0" izz="0.00510213333333"/>
    </inertial>
  </link>
  <joint name="leftleg_knee_foot/OUTPUT_JOINT" type="fixed">
    <parent link="leftleg_knee_foot/INPUT_INTERFACE"/>
    <child link="leftleg/foot/INPUT_INTERFACE"/>
    <origin rpy="3.14159265359 0 0" xyz="0.38 -2.44929359829e-18 0.0"/>
  </joint>
  <gazebo reference="leftleg_knee_foot/INPUT_INTERFACE">
    <selfCollide>true</selfCollide>
    <material>Gazebo/FlatBlack</material>
  </gazebo>
  <link name="leftleg/foot/INPUT_INTERFACE">
    <visual>
      <origin rpy="0 0 0" xyz="0 0 0"/>
      <geometry>
        <mesh filename="package://hebiros_description/meshes/x5.stl" scale="0.001 0.001 0.001"/>
      </geometry>
      <material name="red">
        <color rgba=".82 0.06 0.06 1"/>
      </material>
    </visual>
    <collision>
      <origin rpy="0 0 0" xyz="0 0 0"/>
      <geometry>
        <mesh filename="package://hebiros_description/meshes/x5.stl" scale="0.001 0.001 0.001"/>
      </geometry>
    </collision>
    <inertial>
      <origin rpy="0 0 0" xyz="-0.0142 -0.0031 0.0165"/>
      <mass value="0.335"/>
      <inertia ixx="0.00015" ixy="0.0000341" ixz="0.0000118" iyy="0.000255" iyz="0.00000229" izz="0.000350"/>
    </inertial>
  </link>
  <joint name="leftleg/foot/X5_4" type="continuous">
    <parent link="leftleg/foot/INPUT_INTERFACE"/>
    <child link="leftleg_end_effector/INPUT_INTERFACE"/>
    <origin rpy="0 0 0" xyz="0 0 0.031"/>
    <axis xyz="0 0 1"/>
    <limit effort="7.0" velocity="32"/>
    <dynamics damping="0.1" friction="0.1"/>
  </joint>
  <gazebo reference="leftleg/foot/INPUT_INTERFACE">
    <selfCollide>true</selfCollide>
    <gravity>true</gravity>
    <sensor name="leftleg/foot/imu_sensor" type="imu">
      <always_on>true</always_on>
      <update_rate>100</update_rate>
      <visualize>true</visualize>
      <plugin filename="libgazebo_ros_imu_sensor.so" name="imu_plugin">
        <topicName>/hebiros_gazebo_plugin/imu/leftleg/foot</topicName>
        <bodyName>leftleg/foot/imu_link</bodyName>
        <updateRateHZ>10.0</updateRateHZ>
        <gaussianNoise>0.0</gaussianNoise>
        <xyzOffset>0.025 0 0.003</xyzOffset>
        <rpyOffset>0 0 0</rpyOffset>
        <frameName>leftleg/foot/imu_link</frameName>
      </plugin>
      <pose>0 0 0 0 0 0</pose>
    </sensor>
    <material>Gazebo/BlueGlow</material>
  </gazebo>
  <link name="rightleg/base/INPUT_INTERFACE">
    <visual>
      <origin rpy="0 0 0" xyz="0 0 0"/>
      <geometry>
        <mesh filename="package://hebiros_description/meshes/x5.stl" scale="0.001 0.001 0.001"/>
      </geometry>
      <material name="red">
        <color rgba=".82 0.06 0.06 1"/>
      </material>
    </visual>
    <collision>
      <origin rpy="0 0 0" xyz="0 0 0"/>
      <geometry>
        <mesh filename="package://hebiros_description/meshes/x5.stl" scale="0.001 0.001 0.001"/>
      </geometry>
    </collision>
    <inertial>
      <origin rpy="0 0 0" xyz="-0.0142 -0.0031 0.0165"/>
      <mass value="0.335"/>
      <inertia ixx="0.00015" ixy="0.0000341" ixz="0.0000118" iyy="0.000255" iyz="0.00000229" izz="0.000350"/>
    </inertial>
  </link>
  <joint name="rightleg/base/X5_4" type="continuous">
    <parent link="rightleg/base/INPUT_INTERFACE"/>
    <child link="rightleg_base_knee/INPUT_INTERFACE"/>
    <origin rpy="0 0 0" xyz="0 0 0.031"/>
    <axis xyz="0 0 1"/>
    <limit effort="7.0" velocity="32"/>
    <dynamics damping="0.1" friction="0.1"/>
  </joint>
  <gazebo reference="rightleg/base/INPUT_INTERFACE">
    <selfCollide>true</selfCollide>
    <gravity>true</gravity>
    <sensor name="rightleg/base/imu_sensor" type="imu">
      <always_on>true</always_on>
      <update_rate>100</update_rate>
      <visualize>true</visualize>
      <plugin filename="libgazebo_ros_imu_sensor.so" name="imu_plugin">
        <topicName>/hebiros_gazebo_plugin/imu/rightleg/base</topicName>
        <bodyName>rightleg/base/imu_link</bodyName>
        <updateRateHZ>10.0</updateRateHZ>
        <gaussianNoise>0.0</gaussianNoise>
        <xyzOffset>0.025 0 0.003</xyzOffset>
        <rpyOffset>0 0 0</rpyOffset>
        <frameName>rightleg/base/imu_link</frameName>
      </plugin>
      <pose>0 0 0 0 0 0</pose>
    </sensor>
    <material>Gazebo/BlueGlow</material>
  </gazebo>
  <link name="rightleg_base_knee/INPUT_INTERFACE">
    <visual>
      <origin rpy="0 0 0" xyz="0 0 0"/>
      <geometry>
        <mesh filename="package://hebiros_description/meshes/A-2038-02.stl"/>
      </geometry>
      <material name="black">
        <color rgba="0 0 0 1"/>
      </material>
    </visual>
    <visual>
      <origin rpy="0 1.57075 0" xyz="0.19 0 0.02"/>
      <geometry>
        <cylinder length="0.3546" radius=".016"/>
      </geometry>
      <material name="silver">
        <color rgba="0.6 0.6 0.6 1"/>
      </material>
    </visual>
    <visual>
      <origin rpy="-3.14159265359 0 0" xyz="0.38 -2.44929359829e-18 0.0"/>
      <geometry>
        <mesh filename="package://hebiros_description/meshes/A-2039-02.stl"/>
      </geometry>
      <material name="black">
        <color rgba="0 0 0 1"/>
      </material>
    </visual>
    <collision>
      <origin rpy="0 0 0" xyz="0 0 0"/>
      <geometry>
        <mesh filename="package://hebiros_description/meshes/A-2038-02.stl"/>
      </geometry>
    </collision>
    <collision>
      <origin rpy="0 1.57075 0" xyz="0.19 0 0.02"/>
      <geometry>
        <cylinder length="0.3546" radius=".016"/>
      </geometry>
    </collision>
    <collision>
      <origin rpy="-3.14159265359 0 0" xyz="0.38 -2.44929359829e-18 0.0"/>
      <geometry>
        <mesh filename="package://hebiros_description/meshes/A-2039-02.stl"/>
      </geometry>
    </collision>
    <!-- Approximate inertia as thin rod about x axis -->
    <inertial>
      <origin rpy="0 0 0" xyz="0.19 0 0.02"/>
      <mass value="0.424"/>
      <inertia ixx="0.0" ixy="0.0" ixz="0.0" iyy="0.00510213333333" iyz="0.0" izz="0.00510213333333"/>
    </inertial>
  </link>
  <joint name="rightleg_base_knee/OUTPUT_JOINT" type="fixed">
    <parent link="rightleg_base_knee/INPUT_INTERFACE"/>
    <child link="rightleg/knee/INPUT_INTERFACE"/>
    <origin rpy="3.14159265359 0 0" xyz="0.38 -2.44929359829e-18 0.0"/>
  </joint>
  <gazebo reference="rightleg_base_knee/INPUT_INTERFACE">
    <selfCollide>true</selfCollide>
    <material>Gazebo/FlatBlack</material>
  </gazebo>
  <link name="rightleg/knee/INPUT_INTERFACE">
    <visual>
      <origin rpy="0 0 0" xyz="0 0 0"/>
      <geometry>
        <mesh filename="package://hebiros_description/meshes/x5.stl" scale="0.001 0.001 0.001"/>
      </geometry>
      <material name="red">
        <color rgba=".82 0.06 0.06 1"/>
      </material>
    </visual>
    <collision>
      <origin rpy="0 0 0" xyz="0 0 0"/>
      <geometry>
        <mesh filename="package://hebiros_description/meshes/x5.stl" scale="0.001 0.001 0.001"/>
      </geometry>
    </collision>
    <inertial>
      <origin rpy="0 0 0" xyz="-0.0142 -0.0031 0.0165"/>
      <mass value="0.335"/>
      <inertia ixx="0.00015" ixy="0.0000341" ixz="0.0000118" iyy="0.000255" iyz="0.00000229" izz="0.000350"/>
    </inertial>
  </link>
  <joint name="rightleg/knee/X5_4" type="continuous">
    <parent link="rightleg/knee/INPUT_INTERFACE"/>
    <child link="rightleg_knee_foot/INPUT_INTERFACE"/>
    <origin rpy="0 0 0" xyz="0 0 0.031"/>
    <axis xyz="0 0 1"/>
    <limit effort="7.0" velocity="32"/>
    <dynamics damping="0.1" friction="0.1"/>
  </joint>
  <gazebo reference="rightleg/knee/INPUT_INTERFACE">
    <selfCollide>true</selfCollide>
    <gravity>true</gravity>
    <sensor name="rightleg/knee/imu_sensor" type="imu">
      <always_on>true</always_on>
      <update_rate>100</update_rate>
      <visualize>true</visualize>
      <plugin filename="libgazebo_ros_imu_sensor.so" name="imu_plugin">
        <topicName>/hebiros_gazebo_plugin/imu/rightleg/knee</topicName>
        <bodyName>rightleg/knee/imu_link</bodyName>
        <updateRateHZ>10.0</updateRateHZ>
        <gaussianNoise>0.0</gaussianNoise>
        <xyzOffset>0.025 0 0.003</xyzOffset>
        <rpyOffset>0 0 0</rpyOffset>
        <frameName>rightleg/knee/imu_link</frameName>
      </plugin>
      <pose>0 0 0 0 0 0</pose>
    </sensor>
    <material>Gazebo/BlueGlow</material>
  </gazebo>
  <link name="rightleg_knee_foot/INPUT_INTERFACE">
    <visual>
      <origin rpy="0 0 0" xyz="0 0 0"/>
      <geometry>
        <mesh filename="package://hebiros_description/meshes/A-2038-02.stl"/>
      </geometry>
      <material name="black">
        <color rgba="0 0 0 1"/>
      </material>
    </visual>
    <visual>
      <origin rpy="0 1.57075 0" xyz="0.19 0 0.02"/>
      <geometry>
        <cylinder length="0.3546" radius=".016"/>
      </geometry>
      <material name="silver">
        <color rgba="0.6 0.6 0.6 1"/>
      </material>
    </visual>
    <visual>
      <origin rpy="-3.14159265359 0 0" xyz="0.38 -2.44929359829e-18 0.0"/>
      <geometry>
        <mesh filename="package://hebiros_description/meshes/A-2039-02.stl"/>
      </geometry>
      <material name="black">
        <color rgba="0 0 0 1"/>
      </material>
    </visual>
    <collision>
      <origin rpy="0 0 0" xyz="0 0 0"/>
      <geometry>
        <mesh filename="package://hebiros_description/meshes/A-2038-02.stl"/>
      </geometry>
    </collision>
    <collision>
      <origin rpy="0 1.57075 0" xyz="0.19 0 0.02"/>
      <geometry>
        <cylinder length="0.3546" radius=".016"/>
      </geometry>
    </collision>
    <collision>
      <origin rpy="-3.14159265359 0 0" xyz="0.38 -2.44929359829e-18 0.0"/>
      <geometry>
        <mesh filename="package://hebiros_description/meshes/A-2039-02.stl"/>
      </geometry>
    </collision>
    <!-- Approximate inertia as thin rod about x axis -->
    <inertial>
      <origin rpy="0 0 0" xyz="0.19 0 0.02"/>
      <mass value="0.424"/>
      <inertia ixx="0.0" ixy="0.0" ixz="0.0" iyy="0.00510213333333" iyz="0.0" izz="0.00510213333333"/>
    </inertial>
  </link>
  <joint name="rightleg_knee_foot/OUTPUT_JOINT" type="fixed">
    <parent link="rightleg_knee_foot/INPUT_INTERFACE"/>
    <child link="rightleg/foot/INPUT_INTERFACE"/>
    <origin rpy="3.14159265359 0 0" xyz="0.38 -2.44929359829e-18 0.0"/>
  </joint>
  <gazebo reference="rightleg_knee_foot/INPUT_INTERFACE">
    <selfCollide>true</selfCollide>
    <material>Gazebo/FlatBlack</material>
  </gazebo>
  <link name="rightleg/foot/INPUT_INTERFACE">
    <visual>
      <origin rpy="0 0 0" xyz="0 0 0"/>
      <geometry>
        <mesh filename="package://hebiros_description/meshes/x5.stl" scale="0.001 0.001 0.001"/>
      </geometry>
      <material name="red">
        <color rgba=".82 0.06 0.06 1"/>
      </material>
    </visual>
    <collision>
      <origin rpy="0 0 0" xyz="0 0 0"/>
      <geometry>
        <mesh filename="package://hebiros_description/meshes/x5.stl" scale="0.001 0.001 0.001"/>
      </geometry>
    </collision>
    <inertial>
      <origin rpy="0 0 0" xyz="-0.0142 -0.0031 0.0165"/>
      <mass value="0.335"/>
      <inertia ixx="0.00015" ixy="0.0000341" ixz="0.0000118" iyy="0.000255" iyz="0.00000229" izz="0.000350"/>
    </inertial>
  </link>
  <joint name="rightleg/foot/X5_4" type="continuous">
    <parent link="rightleg/foot/INPUT_INTERFACE"/>
    <child link="rightleg_end_effector/INPUT_INTERFACE"/>
    <origin rpy="0 0 0" xyz="0 0 0.031"/>
    <axis xyz="0 0 1"/>
    <limit effort="7.0" velocity="32"/>
    <dynamics damping="0.1" friction="0.1"/>
  </joint>
  <gazebo reference="rightleg/foot/INPUT_INTERFACE">
    <selfCollide>true</selfCollide>
    <gravity>true</gravity>
    <sensor name="rightleg/foot/imu_sensor" type="imu">
      <always_on>true</always_on>
      <update_rate>100</update_rate>
      <visualize>true</visualize>
      <plugin filename="libgazebo_ros_imu_sensor.so" name="imu_plugin">
        <topicName>/hebiros_gazebo_plugin/imu/rightleg/foot</topicName>
        <bodyName>rightleg/foot/imu_link</bodyName>
        <updateRateHZ>10.0</updateRateHZ>
        <gaussianNoise>0.0</gaussianNoise>
        <xyzOffset>0.025 0 0.003</xyzOffset>
        <rpyOffset>0 0 0</rpyOffset>
        <frameName>rightleg/foot/imu_link</frameName>
      </plugin>
      <pose>0 0 0 0 0 0</pose>
    </sensor>
    <material>Gazebo/BlueGlow</material>
  </gazebo>
  <!-- end links -->
  <link name="leftarm_end_effector/INPUT_INTERFACE">
  </link>
  <link name="rightarm_end_effector/INPUT_INTERFACE">
  </link>
  <link name="leftleg_end_effector/INPUT_INTERFACE">
  </link>
  <link name="rightleg_end_effector/INPUT_INTERFACE">
  </link>
  <gazebo>
    <plugin filename="libhebiros_gazebo_plugin.so" name="hebiros_gazebo_plugin">
    </plugin>
  </gazebo>
</robot>

