<?xml version="1.0"?>
<robot xmlns:xacro="http://www.ros.org/wiki/xacro">
  <!-- NOTE: joint must match the name of the module -->
  <xacro:macro name="x5" params="joint child model">
  <xacro:property name="model_name" value="${model}"/>
    <link name="${joint}/INPUT_INTERFACE">
      <visual>
        <origin xyz="0 0 0" rpy="0 0 0" />
        <geometry>
          <mesh filename="package://hebiros_description/meshes/x5.stl" scale="0.001 0.001 0.001"/>
        </geometry>
        <xacro:red_material/>
      </visual>
      <collision>
        <origin xyz="0 0 0" rpy="0 0 0" />
        <geometry>
          <mesh filename="package://hebiros_description/meshes/x5.stl" scale="0.001 0.001 0.001"/>
        </geometry>
      </collision>
      <inertial>
        <origin xyz="-0.0142 -0.0031 0.0165" rpy="0 0 0" />
        <xacro:if value="${model_name == 'X5_1'}">
          <mass value="0.315"/>
        </xacro:if>
        <xacro:if value="${model_name == 'X5_4'}">
          <mass value="0.335"/>
        </xacro:if>
        <xacro:if value="${model_name == 'X5_9'}">
          <mass value="0.360"/>
        </xacro:if>
        <inertia ixx="0.00015" iyy="0.000255" izz="0.000350" ixy="0.0000341" ixz="0.0000118" iyz="0.00000229"/>
      </inertial>
    </link>
    <xacro:if value="${model_name == 'X5_1'}">
      <joint name="${joint}/X5_1" type="continuous">
        <parent link="${joint}/INPUT_INTERFACE"/>
        <child link="${child}/INPUT_INTERFACE"/>
        <origin xyz="0 0 0.031" rpy="0 0 0"/>
        <axis xyz="0 0 1"/>
        <limit effort="2.5" velocity="90"/>
        <dynamics damping="0.1" friction="0.1"/>
      </joint>
    </xacro:if>
    <xacro:if value="${model_name == 'X5_4'}">
      <joint name="${joint}/X5_4" type="continuous">
        <parent link="${joint}/INPUT_INTERFACE"/>
        <child link="${child}/INPUT_INTERFACE"/>
        <origin xyz="0 0 0.031" rpy="0 0 0"/>
        <axis xyz="0 0 1"/>
        <limit effort="7.0" velocity="32"/>
        <dynamics damping="0.1" friction="0.1"/>
      </joint>
    </xacro:if>
    <xacro:if value="${model_name == 'X5_9'}">
      <joint name="${joint}/X5_9" type="continuous">
        <parent link="${joint}/INPUT_INTERFACE"/>
        <child link="${child}/INPUT_INTERFACE"/>
        <origin xyz="0 0 0.031" rpy="0 0 0"/>
        <axis xyz="0 0 1"/>
        <limit effort="13.0" velocity="14"/>
        <dynamics damping="0.1" friction="0.1"/>
      </joint>
    </xacro:if>
    <gazebo reference="${joint}/INPUT_INTERFACE">
      <selfCollide>true</selfCollide>
      <gravity>true</gravity>
      <sensor name="${joint}/imu_sensor" type="imu">
        <always_on>true</always_on>
        <update_rate>100</update_rate>
        <visualize>true</visualize>
        <plugin filename="libgazebo_ros_imu_sensor.so" name="imu_plugin">
          <topicName>/hebiros_gazebo_plugin/imu/${joint}</topicName>
          <bodyName>${joint}/imu_link</bodyName>
          <updateRateHZ>10.0</updateRateHZ>
          <gaussianNoise>0.0</gaussianNoise>
          <xyzOffset>0.025 0 0.003</xyzOffset>
          <rpyOffset>0 0 0</rpyOffset>
          <frameName>${joint}/imu_link</frameName>
        </plugin>
        <pose>0 0 0 0 0 0</pose>
      </sensor>
    </gazebo>
  </xacro:macro>
</robot>

