<?xml version="1.0"?>
<robot xmlns:xacro="http://www.ros.org/wiki/xacro">
  <!-- NOTE: joint must match the name of the module -->
  <xacro:macro name="x8" params="joint child model">
  <xacro:property name="model_name" value="${model}"/>
    <link name="${joint}/INPUT_INTERFACE">
      <visual>
        <origin xyz="0 0 0" rpy="0 0 0" />
        <geometry>
          <mesh filename="package://hebiros_description/meshes/x8.stl" scale="0.001 0.001 0.001"/>
        </geometry>
        <xacro:red_material/>
      </visual>
      <collision>
        <origin xyz="0 0 0" rpy="0 0 0" />
        <geometry>
          <mesh filename="package://hebiros_description/meshes/x8.stl" scale="0.001 0.001 0.001"/>
        </geometry>
      </collision>
      <inertial>
        <origin xyz="-0.0145 -0.0031 0.0242" rpy="0 0 0" />
        <xacro:if value="${model_name == 'X8_3'}">
          <mass value="0.460"/>
        </xacro:if>
        <xacro:if value="${model_name == 'X8_9'}">
          <mass value="0.480"/>
        </xacro:if>
        <xacro:if value="${model_name == 'X8_16'}">
          <mass value="0.500"/>
        </xacro:if>
        <inertia ixx="0.000246" iyy="0.000380" izz="0.000463" ixy="0.0000444" ixz="0.0000266" iyz="0.00000422"/>
      </inertial>
    </link>
    <xacro:if value="${model_name == 'X8_3'}">
      <joint name="${joint}/X8_3" type="continuous">
        <parent link="${joint}/INPUT_INTERFACE"/>
        <child link="${child}/INPUT_INTERFACE"/>
        <origin xyz="0 0 0.045" rpy="0 0 0"/>
        <axis xyz="0 0 1"/>
        <limit effort="7" velocity="84"/>
        <dynamics damping="0.5" friction="0.5"/>
      </joint>
    </xacro:if>
    <xacro:if value="${model_name == 'X8_9'}">
      <joint name="${joint}/X8_9" type="continuous">
        <parent link="${joint}/INPUT_INTERFACE"/>
        <child link="${child}/INPUT_INTERFACE"/>
        <origin xyz="0 0 0.045" rpy="0 0 0"/>
        <axis xyz="0 0 1"/>
        <limit effort="20" velocity="30"/>
        <dynamics damping="0.5" friction="0.5"/>
      </joint>
    </xacro:if>
    <xacro:if value="${model_name == 'X8_16'}">
      <joint name="${joint}/X8_16" type="continuous">
        <parent link="${joint}/INPUT_INTERFACE"/>
        <child link="${child}/INPUT_INTERFACE"/>
        <origin xyz="0 0 0.045" rpy="0 0 0"/>
        <axis xyz="0 0 1"/>
        <limit effort="38" velocity="15"/>
        <dynamics damping="0.5" friction="0.5"/>
      </joint>
    </xacro:if>
    <transmission name="${joint}/transmission">
      <type>transmission_interface/SimpleTransmission</type>
      <joint name="${joint}">
        <hardwareInterface>hardware_interface/EffortJointInterface</hardwareInterface>
      </joint>
      <actuator name="${joint}/actuator">
        <hardwareInterface>hardware_interface/EffortJointInterface</hardwareInterface>
        <mechanicalReduction>1</mechanicalReduction>
      </actuator>
    </transmission>
    <gazebo reference="${joint}/INPUT_INTERFACE">
      <selfCollide>true</selfCollide>
      <gravity>true</gravity>
      <sensor name="${joint}/imu_sensor" type="imu">
        <always_on>true</always_on>
        <update_rate>100</update_rate>
        <visualize>true</visualize>
        <plugin filename="libgazebo_ros_imu_sensor.so" name="imu_plugin">
          <topicName>/hebiros_gazebo_plugin/imu/${joint}</topicName>
          <bodyName>${joint}/imu_link</bodyName>
          <updateRateHZ>10.0</updateRateHZ>
          <gaussianNoise>0.0</gaussianNoise>
          <xyzOffset>0.025 0 0.003</xyzOffset>
          <rpyOffset>0 0 0</rpyOffset>
          <frameName>${joint}/imu_link</frameName>
        </plugin>
        <pose>0 0 0 0 0 0</pose>
      </sensor>
    </gazebo>
  </xacro:macro>
</robot>

